<?xml version="1.0" encoding="UTF-8"?>
<testsuite name="test_cancellation_tests.TestCancellation-20220520232133" tests="59" file="test_cancellation_tests.py" time="0.262" timestamp="2022-05-20T23:21:34" failures="59" errors="0" skipped="0">
	<testcase classname="test_cancellation_tests.TestCancellation" name="test_Json_Case_Valid" time="0.010" timestamp="2022-05-20T23:21:34">
		<failure type="AssertionError" message="None != 'ced0953d112ab693b83d1ced965fcc670b558235361b9d1bd62536769a1efa3b'"><![CDATA[Traceback (most recent call last):
  File "/usr/local/Cellar/python@3.8/3.8.12_1/Frameworks/Python.framework/Versions/3.8/lib/python3.8/unittest/case.py", line 60, in testPartExecutor
    yield
  File "/usr/local/Cellar/python@3.8/3.8.12_1/Frameworks/Python.framework/Versions/3.8/lib/python3.8/unittest/case.py", line 676, in run
    self._callTestMethod(testMethod)
  File "/usr/local/Cellar/python@3.8/3.8.12_1/Frameworks/Python.framework/Versions/3.8/lib/python3.8/unittest/case.py", line 633, in _callTestMethod
    method()
  File "/Users/aaron/PycharmProjects/G89.2022.T21.FP/venv/lib/python3.8/site-packages/freezegun/api.py", line 789, in wrapper
    result = func(*args, **kwargs)
  File "/Users/aaron/PycharmProjects/G89.2022.T21.FP/src/unittest/python/test_cancellation_tests.py", line 196, in test_Json_Case_Valid
    self.assertEqual(date_signature, expected_date_signature)
  File "/usr/local/Cellar/python@3.8/3.8.12_1/Frameworks/Python.framework/Versions/3.8/lib/python3.8/unittest/case.py", line 912, in assertEqual
    assertion_func(first, second, msg=msg)
  File "/usr/local/Cellar/python@3.8/3.8.12_1/Frameworks/Python.framework/Versions/3.8/lib/python3.8/unittest/case.py", line 905, in _baseAssertEqual
    raise self.failureException(msg)
AssertionError: None != 'ced0953d112ab693b83d1ced965fcc670b558235361b9d1bd62536769a1efa3b'
]]></failure>
	</testcase>
	<testcase classname="test_cancellation_tests.TestCancellation" name="test_not_valid_appointment_already_cancelled" time="0.005" timestamp="2022-05-20T23:21:34">
		<failure type="AssertionError" message="VaccineManagementException not raised"><![CDATA[Traceback (most recent call last):
  File "/usr/local/Cellar/python@3.8/3.8.12_1/Frameworks/Python.framework/Versions/3.8/lib/python3.8/unittest/case.py", line 60, in testPartExecutor
    yield
  File "/usr/local/Cellar/python@3.8/3.8.12_1/Frameworks/Python.framework/Versions/3.8/lib/python3.8/unittest/case.py", line 676, in run
    self._callTestMethod(testMethod)
  File "/usr/local/Cellar/python@3.8/3.8.12_1/Frameworks/Python.framework/Versions/3.8/lib/python3.8/unittest/case.py", line 633, in _callTestMethod
    method()
  File "/Users/aaron/PycharmProjects/G89.2022.T21.FP/venv/lib/python3.8/site-packages/freezegun/api.py", line 789, in wrapper
    result = func(*args, **kwargs)
  File "/Users/aaron/PycharmProjects/G89.2022.T21.FP/src/unittest/python/test_cancellation_tests.py", line 297, in test_not_valid_appointment_already_cancelled
    date_signature = my_manager.cancel_appointment(cancellation_json)
  File "/usr/local/Cellar/python@3.8/3.8.12_1/Frameworks/Python.framework/Versions/3.8/lib/python3.8/unittest/case.py", line 227, in __exit__
    self._raiseFailure("{} not raised".format(exc_name))
  File "/usr/local/Cellar/python@3.8/3.8.12_1/Frameworks/Python.framework/Versions/3.8/lib/python3.8/unittest/case.py", line 164, in _raiseFailure
    raise self.test_case.failureException(msg)
AssertionError: VaccineManagementException not raised
]]></failure>
	</testcase>
	<testcase classname="test_cancellation_tests.TestCancellation" name="test_not_valid_appointment_does_not_exist" time="0.005" timestamp="2022-05-20T23:21:34">
		<failure type="AssertionError" message="VaccineManagementException not raised"><![CDATA[Traceback (most recent call last):
  File "/usr/local/Cellar/python@3.8/3.8.12_1/Frameworks/Python.framework/Versions/3.8/lib/python3.8/unittest/case.py", line 60, in testPartExecutor
    yield
  File "/usr/local/Cellar/python@3.8/3.8.12_1/Frameworks/Python.framework/Versions/3.8/lib/python3.8/unittest/case.py", line 676, in run
    self._callTestMethod(testMethod)
  File "/usr/local/Cellar/python@3.8/3.8.12_1/Frameworks/Python.framework/Versions/3.8/lib/python3.8/unittest/case.py", line 633, in _callTestMethod
    method()
  File "/Users/aaron/PycharmProjects/G89.2022.T21.FP/venv/lib/python3.8/site-packages/freezegun/api.py", line 789, in wrapper
    result = func(*args, **kwargs)
  File "/Users/aaron/PycharmProjects/G89.2022.T21.FP/src/unittest/python/test_cancellation_tests.py", line 239, in test_not_valid_appointment_does_not_exist
    date_signature = my_manager.cancel_appointment(cancellation_json)
  File "/usr/local/Cellar/python@3.8/3.8.12_1/Frameworks/Python.framework/Versions/3.8/lib/python3.8/unittest/case.py", line 227, in __exit__
    self._raiseFailure("{} not raised".format(exc_name))
  File "/usr/local/Cellar/python@3.8/3.8.12_1/Frameworks/Python.framework/Versions/3.8/lib/python3.8/unittest/case.py", line 164, in _raiseFailure
    raise self.test_case.failureException(msg)
AssertionError: VaccineManagementException not raised
]]></failure>
	</testcase>
	<testcase classname="test_cancellation_tests.TestCancellation" name="test_not_valid_appointment_is_outdated" time="0.005" timestamp="2022-05-20T23:21:34">
		<failure type="AssertionError" message="VaccineManagementException not raised"><![CDATA[Traceback (most recent call last):
  File "/usr/local/Cellar/python@3.8/3.8.12_1/Frameworks/Python.framework/Versions/3.8/lib/python3.8/unittest/case.py", line 60, in testPartExecutor
    yield
  File "/usr/local/Cellar/python@3.8/3.8.12_1/Frameworks/Python.framework/Versions/3.8/lib/python3.8/unittest/case.py", line 676, in run
    self._callTestMethod(testMethod)
  File "/usr/local/Cellar/python@3.8/3.8.12_1/Frameworks/Python.framework/Versions/3.8/lib/python3.8/unittest/case.py", line 633, in _callTestMethod
    method()
  File "/Users/aaron/PycharmProjects/G89.2022.T21.FP/venv/lib/python3.8/site-packages/freezegun/api.py", line 789, in wrapper
    result = func(*args, **kwargs)
  File "/Users/aaron/PycharmProjects/G89.2022.T21.FP/src/unittest/python/test_cancellation_tests.py", line 268, in test_not_valid_appointment_is_outdated
    date_signature = my_manager.cancel_appointment(cancellation_json)
  File "/usr/local/Cellar/python@3.8/3.8.12_1/Frameworks/Python.framework/Versions/3.8/lib/python3.8/unittest/case.py", line 227, in __exit__
    self._raiseFailure("{} not raised".format(exc_name))
  File "/usr/local/Cellar/python@3.8/3.8.12_1/Frameworks/Python.framework/Versions/3.8/lib/python3.8/unittest/case.py", line 164, in _raiseFailure
    raise self.test_case.failureException(msg)
AssertionError: VaccineManagementException not raised
]]></failure>
	</testcase>
	<testcase classname="test_cancellation_tests.TestCancellation" name="test_parametrized_Json_Case_NV (test='Case_NV_02')" time="0.000" timestamp="0001-01-01T00:00:00">
		<failure type="AssertionError" message="VaccineManagementException not raised"><![CDATA[Traceback (most recent call last):
  File "/usr/local/Cellar/python@3.8/3.8.12_1/Frameworks/Python.framework/Versions/3.8/lib/python3.8/unittest/case.py", line 60, in testPartExecutor
    yield
  File "/usr/local/Cellar/python@3.8/3.8.12_1/Frameworks/Python.framework/Versions/3.8/lib/python3.8/unittest/case.py", line 582, in subTest
    yield
  File "/Users/aaron/PycharmProjects/G89.2022.T21.FP/src/unittest/python/test_cancellation_tests.py", line 219, in test_parametrized_Json_Case_NV
    date_signature = my_manager.cancel_appointment(cancellation_json)
  File "/usr/local/Cellar/python@3.8/3.8.12_1/Frameworks/Python.framework/Versions/3.8/lib/python3.8/unittest/case.py", line 227, in __exit__
    self._raiseFailure("{} not raised".format(exc_name))
  File "/usr/local/Cellar/python@3.8/3.8.12_1/Frameworks/Python.framework/Versions/3.8/lib/python3.8/unittest/case.py", line 164, in _raiseFailure
    raise self.test_case.failureException(msg)
AssertionError: VaccineManagementException not raised
]]></failure>
	</testcase>
	<testcase classname="test_cancellation_tests.TestCancellation" name="test_parametrized_Json_Case_NV (test='Case_NV_03')" time="0.000" timestamp="0001-01-01T00:00:00">
		<failure type="AssertionError" message="VaccineManagementException not raised"><![CDATA[Traceback (most recent call last):
  File "/usr/local/Cellar/python@3.8/3.8.12_1/Frameworks/Python.framework/Versions/3.8/lib/python3.8/unittest/case.py", line 60, in testPartExecutor
    yield
  File "/usr/local/Cellar/python@3.8/3.8.12_1/Frameworks/Python.framework/Versions/3.8/lib/python3.8/unittest/case.py", line 582, in subTest
    yield
  File "/Users/aaron/PycharmProjects/G89.2022.T21.FP/src/unittest/python/test_cancellation_tests.py", line 219, in test_parametrized_Json_Case_NV
    date_signature = my_manager.cancel_appointment(cancellation_json)
  File "/usr/local/Cellar/python@3.8/3.8.12_1/Frameworks/Python.framework/Versions/3.8/lib/python3.8/unittest/case.py", line 227, in __exit__
    self._raiseFailure("{} not raised".format(exc_name))
  File "/usr/local/Cellar/python@3.8/3.8.12_1/Frameworks/Python.framework/Versions/3.8/lib/python3.8/unittest/case.py", line 164, in _raiseFailure
    raise self.test_case.failureException(msg)
AssertionError: VaccineManagementException not raised
]]></failure>
	</testcase>
	<testcase classname="test_cancellation_tests.TestCancellation" name="test_parametrized_Json_Case_NV (test='Case_NV_04')" time="0.000" timestamp="0001-01-01T00:00:00">
		<failure type="AssertionError" message="VaccineManagementException not raised"><![CDATA[Traceback (most recent call last):
  File "/usr/local/Cellar/python@3.8/3.8.12_1/Frameworks/Python.framework/Versions/3.8/lib/python3.8/unittest/case.py", line 60, in testPartExecutor
    yield
  File "/usr/local/Cellar/python@3.8/3.8.12_1/Frameworks/Python.framework/Versions/3.8/lib/python3.8/unittest/case.py", line 582, in subTest
    yield
  File "/Users/aaron/PycharmProjects/G89.2022.T21.FP/src/unittest/python/test_cancellation_tests.py", line 219, in test_parametrized_Json_Case_NV
    date_signature = my_manager.cancel_appointment(cancellation_json)
  File "/usr/local/Cellar/python@3.8/3.8.12_1/Frameworks/Python.framework/Versions/3.8/lib/python3.8/unittest/case.py", line 227, in __exit__
    self._raiseFailure("{} not raised".format(exc_name))
  File "/usr/local/Cellar/python@3.8/3.8.12_1/Frameworks/Python.framework/Versions/3.8/lib/python3.8/unittest/case.py", line 164, in _raiseFailure
    raise self.test_case.failureException(msg)
AssertionError: VaccineManagementException not raised
]]></failure>
	</testcase>
	<testcase classname="test_cancellation_tests.TestCancellation" name="test_parametrized_Json_Case_NV (test='Case_NV_05')" time="0.000" timestamp="0001-01-01T00:00:00">
		<failure type="AssertionError" message="VaccineManagementException not raised"><![CDATA[Traceback (most recent call last):
  File "/usr/local/Cellar/python@3.8/3.8.12_1/Frameworks/Python.framework/Versions/3.8/lib/python3.8/unittest/case.py", line 60, in testPartExecutor
    yield
  File "/usr/local/Cellar/python@3.8/3.8.12_1/Frameworks/Python.framework/Versions/3.8/lib/python3.8/unittest/case.py", line 582, in subTest
    yield
  File "/Users/aaron/PycharmProjects/G89.2022.T21.FP/src/unittest/python/test_cancellation_tests.py", line 219, in test_parametrized_Json_Case_NV
    date_signature = my_manager.cancel_appointment(cancellation_json)
  File "/usr/local/Cellar/python@3.8/3.8.12_1/Frameworks/Python.framework/Versions/3.8/lib/python3.8/unittest/case.py", line 227, in __exit__
    self._raiseFailure("{} not raised".format(exc_name))
  File "/usr/local/Cellar/python@3.8/3.8.12_1/Frameworks/Python.framework/Versions/3.8/lib/python3.8/unittest/case.py", line 164, in _raiseFailure
    raise self.test_case.failureException(msg)
AssertionError: VaccineManagementException not raised
]]></failure>
	</testcase>
	<testcase classname="test_cancellation_tests.TestCancellation" name="test_parametrized_Json_Case_NV (test='Case_NV_06')" time="0.000" timestamp="0001-01-01T00:00:00">
		<failure type="AssertionError" message="VaccineManagementException not raised"><![CDATA[Traceback (most recent call last):
  File "/usr/local/Cellar/python@3.8/3.8.12_1/Frameworks/Python.framework/Versions/3.8/lib/python3.8/unittest/case.py", line 60, in testPartExecutor
    yield
  File "/usr/local/Cellar/python@3.8/3.8.12_1/Frameworks/Python.framework/Versions/3.8/lib/python3.8/unittest/case.py", line 582, in subTest
    yield
  File "/Users/aaron/PycharmProjects/G89.2022.T21.FP/src/unittest/python/test_cancellation_tests.py", line 219, in test_parametrized_Json_Case_NV
    date_signature = my_manager.cancel_appointment(cancellation_json)
  File "/usr/local/Cellar/python@3.8/3.8.12_1/Frameworks/Python.framework/Versions/3.8/lib/python3.8/unittest/case.py", line 227, in __exit__
    self._raiseFailure("{} not raised".format(exc_name))
  File "/usr/local/Cellar/python@3.8/3.8.12_1/Frameworks/Python.framework/Versions/3.8/lib/python3.8/unittest/case.py", line 164, in _raiseFailure
    raise self.test_case.failureException(msg)
AssertionError: VaccineManagementException not raised
]]></failure>
	</testcase>
	<testcase classname="test_cancellation_tests.TestCancellation" name="test_parametrized_Json_Case_NV (test='Case_NV_07')" time="0.000" timestamp="0001-01-01T00:00:00">
		<failure type="AssertionError" message="VaccineManagementException not raised"><![CDATA[Traceback (most recent call last):
  File "/usr/local/Cellar/python@3.8/3.8.12_1/Frameworks/Python.framework/Versions/3.8/lib/python3.8/unittest/case.py", line 60, in testPartExecutor
    yield
  File "/usr/local/Cellar/python@3.8/3.8.12_1/Frameworks/Python.framework/Versions/3.8/lib/python3.8/unittest/case.py", line 582, in subTest
    yield
  File "/Users/aaron/PycharmProjects/G89.2022.T21.FP/src/unittest/python/test_cancellation_tests.py", line 219, in test_parametrized_Json_Case_NV
    date_signature = my_manager.cancel_appointment(cancellation_json)
  File "/usr/local/Cellar/python@3.8/3.8.12_1/Frameworks/Python.framework/Versions/3.8/lib/python3.8/unittest/case.py", line 227, in __exit__
    self._raiseFailure("{} not raised".format(exc_name))
  File "/usr/local/Cellar/python@3.8/3.8.12_1/Frameworks/Python.framework/Versions/3.8/lib/python3.8/unittest/case.py", line 164, in _raiseFailure
    raise self.test_case.failureException(msg)
AssertionError: VaccineManagementException not raised
]]></failure>
	</testcase>
	<testcase classname="test_cancellation_tests.TestCancellation" name="test_parametrized_Json_Case_NV (test='Case_NV_08')" time="0.000" timestamp="0001-01-01T00:00:00">
		<failure type="AssertionError" message="VaccineManagementException not raised"><![CDATA[Traceback (most recent call last):
  File "/usr/local/Cellar/python@3.8/3.8.12_1/Frameworks/Python.framework/Versions/3.8/lib/python3.8/unittest/case.py", line 60, in testPartExecutor
    yield
  File "/usr/local/Cellar/python@3.8/3.8.12_1/Frameworks/Python.framework/Versions/3.8/lib/python3.8/unittest/case.py", line 582, in subTest
    yield
  File "/Users/aaron/PycharmProjects/G89.2022.T21.FP/src/unittest/python/test_cancellation_tests.py", line 219, in test_parametrized_Json_Case_NV
    date_signature = my_manager.cancel_appointment(cancellation_json)
  File "/usr/local/Cellar/python@3.8/3.8.12_1/Frameworks/Python.framework/Versions/3.8/lib/python3.8/unittest/case.py", line 227, in __exit__
    self._raiseFailure("{} not raised".format(exc_name))
  File "/usr/local/Cellar/python@3.8/3.8.12_1/Frameworks/Python.framework/Versions/3.8/lib/python3.8/unittest/case.py", line 164, in _raiseFailure
    raise self.test_case.failureException(msg)
AssertionError: VaccineManagementException not raised
]]></failure>
	</testcase>
	<testcase classname="test_cancellation_tests.TestCancellation" name="test_parametrized_Json_Case_NV (test='Case_NV_09')" time="0.000" timestamp="0001-01-01T00:00:00">
		<failure type="AssertionError" message="VaccineManagementException not raised"><![CDATA[Traceback (most recent call last):
  File "/usr/local/Cellar/python@3.8/3.8.12_1/Frameworks/Python.framework/Versions/3.8/lib/python3.8/unittest/case.py", line 60, in testPartExecutor
    yield
  File "/usr/local/Cellar/python@3.8/3.8.12_1/Frameworks/Python.framework/Versions/3.8/lib/python3.8/unittest/case.py", line 582, in subTest
    yield
  File "/Users/aaron/PycharmProjects/G89.2022.T21.FP/src/unittest/python/test_cancellation_tests.py", line 219, in test_parametrized_Json_Case_NV
    date_signature = my_manager.cancel_appointment(cancellation_json)
  File "/usr/local/Cellar/python@3.8/3.8.12_1/Frameworks/Python.framework/Versions/3.8/lib/python3.8/unittest/case.py", line 227, in __exit__
    self._raiseFailure("{} not raised".format(exc_name))
  File "/usr/local/Cellar/python@3.8/3.8.12_1/Frameworks/Python.framework/Versions/3.8/lib/python3.8/unittest/case.py", line 164, in _raiseFailure
    raise self.test_case.failureException(msg)
AssertionError: VaccineManagementException not raised
]]></failure>
	</testcase>
	<testcase classname="test_cancellation_tests.TestCancellation" name="test_parametrized_Json_Case_NV (test='Case_NV_10')" time="0.000" timestamp="0001-01-01T00:00:00">
		<failure type="AssertionError" message="VaccineManagementException not raised"><![CDATA[Traceback (most recent call last):
  File "/usr/local/Cellar/python@3.8/3.8.12_1/Frameworks/Python.framework/Versions/3.8/lib/python3.8/unittest/case.py", line 60, in testPartExecutor
    yield
  File "/usr/local/Cellar/python@3.8/3.8.12_1/Frameworks/Python.framework/Versions/3.8/lib/python3.8/unittest/case.py", line 582, in subTest
    yield
  File "/Users/aaron/PycharmProjects/G89.2022.T21.FP/src/unittest/python/test_cancellation_tests.py", line 219, in test_parametrized_Json_Case_NV
    date_signature = my_manager.cancel_appointment(cancellation_json)
  File "/usr/local/Cellar/python@3.8/3.8.12_1/Frameworks/Python.framework/Versions/3.8/lib/python3.8/unittest/case.py", line 227, in __exit__
    self._raiseFailure("{} not raised".format(exc_name))
  File "/usr/local/Cellar/python@3.8/3.8.12_1/Frameworks/Python.framework/Versions/3.8/lib/python3.8/unittest/case.py", line 164, in _raiseFailure
    raise self.test_case.failureException(msg)
AssertionError: VaccineManagementException not raised
]]></failure>
	</testcase>
	<testcase classname="test_cancellation_tests.TestCancellation" name="test_parametrized_Json_Case_NV (test='Case_NV_11')" time="0.000" timestamp="0001-01-01T00:00:00">
		<failure type="AssertionError" message="VaccineManagementException not raised"><![CDATA[Traceback (most recent call last):
  File "/usr/local/Cellar/python@3.8/3.8.12_1/Frameworks/Python.framework/Versions/3.8/lib/python3.8/unittest/case.py", line 60, in testPartExecutor
    yield
  File "/usr/local/Cellar/python@3.8/3.8.12_1/Frameworks/Python.framework/Versions/3.8/lib/python3.8/unittest/case.py", line 582, in subTest
    yield
  File "/Users/aaron/PycharmProjects/G89.2022.T21.FP/src/unittest/python/test_cancellation_tests.py", line 219, in test_parametrized_Json_Case_NV
    date_signature = my_manager.cancel_appointment(cancellation_json)
  File "/usr/local/Cellar/python@3.8/3.8.12_1/Frameworks/Python.framework/Versions/3.8/lib/python3.8/unittest/case.py", line 227, in __exit__
    self._raiseFailure("{} not raised".format(exc_name))
  File "/usr/local/Cellar/python@3.8/3.8.12_1/Frameworks/Python.framework/Versions/3.8/lib/python3.8/unittest/case.py", line 164, in _raiseFailure
    raise self.test_case.failureException(msg)
AssertionError: VaccineManagementException not raised
]]></failure>
	</testcase>
	<testcase classname="test_cancellation_tests.TestCancellation" name="test_parametrized_Json_Case_NV (test='Case_NV_12')" time="0.000" timestamp="0001-01-01T00:00:00">
		<failure type="AssertionError" message="VaccineManagementException not raised"><![CDATA[Traceback (most recent call last):
  File "/usr/local/Cellar/python@3.8/3.8.12_1/Frameworks/Python.framework/Versions/3.8/lib/python3.8/unittest/case.py", line 60, in testPartExecutor
    yield
  File "/usr/local/Cellar/python@3.8/3.8.12_1/Frameworks/Python.framework/Versions/3.8/lib/python3.8/unittest/case.py", line 582, in subTest
    yield
  File "/Users/aaron/PycharmProjects/G89.2022.T21.FP/src/unittest/python/test_cancellation_tests.py", line 219, in test_parametrized_Json_Case_NV
    date_signature = my_manager.cancel_appointment(cancellation_json)
  File "/usr/local/Cellar/python@3.8/3.8.12_1/Frameworks/Python.framework/Versions/3.8/lib/python3.8/unittest/case.py", line 227, in __exit__
    self._raiseFailure("{} not raised".format(exc_name))
  File "/usr/local/Cellar/python@3.8/3.8.12_1/Frameworks/Python.framework/Versions/3.8/lib/python3.8/unittest/case.py", line 164, in _raiseFailure
    raise self.test_case.failureException(msg)
AssertionError: VaccineManagementException not raised
]]></failure>
	</testcase>
	<testcase classname="test_cancellation_tests.TestCancellation" name="test_parametrized_Json_Case_NV (test='Case_NV_13')" time="0.000" timestamp="0001-01-01T00:00:00">
		<failure type="AssertionError" message="VaccineManagementException not raised"><![CDATA[Traceback (most recent call last):
  File "/usr/local/Cellar/python@3.8/3.8.12_1/Frameworks/Python.framework/Versions/3.8/lib/python3.8/unittest/case.py", line 60, in testPartExecutor
    yield
  File "/usr/local/Cellar/python@3.8/3.8.12_1/Frameworks/Python.framework/Versions/3.8/lib/python3.8/unittest/case.py", line 582, in subTest
    yield
  File "/Users/aaron/PycharmProjects/G89.2022.T21.FP/src/unittest/python/test_cancellation_tests.py", line 219, in test_parametrized_Json_Case_NV
    date_signature = my_manager.cancel_appointment(cancellation_json)
  File "/usr/local/Cellar/python@3.8/3.8.12_1/Frameworks/Python.framework/Versions/3.8/lib/python3.8/unittest/case.py", line 227, in __exit__
    self._raiseFailure("{} not raised".format(exc_name))
  File "/usr/local/Cellar/python@3.8/3.8.12_1/Frameworks/Python.framework/Versions/3.8/lib/python3.8/unittest/case.py", line 164, in _raiseFailure
    raise self.test_case.failureException(msg)
AssertionError: VaccineManagementException not raised
]]></failure>
	</testcase>
	<testcase classname="test_cancellation_tests.TestCancellation" name="test_parametrized_Json_Case_NV (test='Case_NV_14')" time="0.000" timestamp="0001-01-01T00:00:00">
		<failure type="AssertionError" message="VaccineManagementException not raised"><![CDATA[Traceback (most recent call last):
  File "/usr/local/Cellar/python@3.8/3.8.12_1/Frameworks/Python.framework/Versions/3.8/lib/python3.8/unittest/case.py", line 60, in testPartExecutor
    yield
  File "/usr/local/Cellar/python@3.8/3.8.12_1/Frameworks/Python.framework/Versions/3.8/lib/python3.8/unittest/case.py", line 582, in subTest
    yield
  File "/Users/aaron/PycharmProjects/G89.2022.T21.FP/src/unittest/python/test_cancellation_tests.py", line 219, in test_parametrized_Json_Case_NV
    date_signature = my_manager.cancel_appointment(cancellation_json)
  File "/usr/local/Cellar/python@3.8/3.8.12_1/Frameworks/Python.framework/Versions/3.8/lib/python3.8/unittest/case.py", line 227, in __exit__
    self._raiseFailure("{} not raised".format(exc_name))
  File "/usr/local/Cellar/python@3.8/3.8.12_1/Frameworks/Python.framework/Versions/3.8/lib/python3.8/unittest/case.py", line 164, in _raiseFailure
    raise self.test_case.failureException(msg)
AssertionError: VaccineManagementException not raised
]]></failure>
	</testcase>
	<testcase classname="test_cancellation_tests.TestCancellation" name="test_parametrized_Json_Case_NV (test='Case_NV_15')" time="0.000" timestamp="0001-01-01T00:00:00">
		<failure type="AssertionError" message="VaccineManagementException not raised"><![CDATA[Traceback (most recent call last):
  File "/usr/local/Cellar/python@3.8/3.8.12_1/Frameworks/Python.framework/Versions/3.8/lib/python3.8/unittest/case.py", line 60, in testPartExecutor
    yield
  File "/usr/local/Cellar/python@3.8/3.8.12_1/Frameworks/Python.framework/Versions/3.8/lib/python3.8/unittest/case.py", line 582, in subTest
    yield
  File "/Users/aaron/PycharmProjects/G89.2022.T21.FP/src/unittest/python/test_cancellation_tests.py", line 219, in test_parametrized_Json_Case_NV
    date_signature = my_manager.cancel_appointment(cancellation_json)
  File "/usr/local/Cellar/python@3.8/3.8.12_1/Frameworks/Python.framework/Versions/3.8/lib/python3.8/unittest/case.py", line 227, in __exit__
    self._raiseFailure("{} not raised".format(exc_name))
  File "/usr/local/Cellar/python@3.8/3.8.12_1/Frameworks/Python.framework/Versions/3.8/lib/python3.8/unittest/case.py", line 164, in _raiseFailure
    raise self.test_case.failureException(msg)
AssertionError: VaccineManagementException not raised
]]></failure>
	</testcase>
	<testcase classname="test_cancellation_tests.TestCancellation" name="test_parametrized_Json_Case_NV (test='Case_NV_16')" time="0.000" timestamp="0001-01-01T00:00:00">
		<failure type="AssertionError" message="VaccineManagementException not raised"><![CDATA[Traceback (most recent call last):
  File "/usr/local/Cellar/python@3.8/3.8.12_1/Frameworks/Python.framework/Versions/3.8/lib/python3.8/unittest/case.py", line 60, in testPartExecutor
    yield
  File "/usr/local/Cellar/python@3.8/3.8.12_1/Frameworks/Python.framework/Versions/3.8/lib/python3.8/unittest/case.py", line 582, in subTest
    yield
  File "/Users/aaron/PycharmProjects/G89.2022.T21.FP/src/unittest/python/test_cancellation_tests.py", line 219, in test_parametrized_Json_Case_NV
    date_signature = my_manager.cancel_appointment(cancellation_json)
  File "/usr/local/Cellar/python@3.8/3.8.12_1/Frameworks/Python.framework/Versions/3.8/lib/python3.8/unittest/case.py", line 227, in __exit__
    self._raiseFailure("{} not raised".format(exc_name))
  File "/usr/local/Cellar/python@3.8/3.8.12_1/Frameworks/Python.framework/Versions/3.8/lib/python3.8/unittest/case.py", line 164, in _raiseFailure
    raise self.test_case.failureException(msg)
AssertionError: VaccineManagementException not raised
]]></failure>
	</testcase>
	<testcase classname="test_cancellation_tests.TestCancellation" name="test_parametrized_Json_Case_NV (test='Case_NV_17')" time="0.000" timestamp="0001-01-01T00:00:00">
		<failure type="AssertionError" message="VaccineManagementException not raised"><![CDATA[Traceback (most recent call last):
  File "/usr/local/Cellar/python@3.8/3.8.12_1/Frameworks/Python.framework/Versions/3.8/lib/python3.8/unittest/case.py", line 60, in testPartExecutor
    yield
  File "/usr/local/Cellar/python@3.8/3.8.12_1/Frameworks/Python.framework/Versions/3.8/lib/python3.8/unittest/case.py", line 582, in subTest
    yield
  File "/Users/aaron/PycharmProjects/G89.2022.T21.FP/src/unittest/python/test_cancellation_tests.py", line 219, in test_parametrized_Json_Case_NV
    date_signature = my_manager.cancel_appointment(cancellation_json)
  File "/usr/local/Cellar/python@3.8/3.8.12_1/Frameworks/Python.framework/Versions/3.8/lib/python3.8/unittest/case.py", line 227, in __exit__
    self._raiseFailure("{} not raised".format(exc_name))
  File "/usr/local/Cellar/python@3.8/3.8.12_1/Frameworks/Python.framework/Versions/3.8/lib/python3.8/unittest/case.py", line 164, in _raiseFailure
    raise self.test_case.failureException(msg)
AssertionError: VaccineManagementException not raised
]]></failure>
	</testcase>
	<testcase classname="test_cancellation_tests.TestCancellation" name="test_parametrized_Json_Case_NV (test='Case_NV_18')" time="0.000" timestamp="0001-01-01T00:00:00">
		<failure type="AssertionError" message="VaccineManagementException not raised"><![CDATA[Traceback (most recent call last):
  File "/usr/local/Cellar/python@3.8/3.8.12_1/Frameworks/Python.framework/Versions/3.8/lib/python3.8/unittest/case.py", line 60, in testPartExecutor
    yield
  File "/usr/local/Cellar/python@3.8/3.8.12_1/Frameworks/Python.framework/Versions/3.8/lib/python3.8/unittest/case.py", line 582, in subTest
    yield
  File "/Users/aaron/PycharmProjects/G89.2022.T21.FP/src/unittest/python/test_cancellation_tests.py", line 219, in test_parametrized_Json_Case_NV
    date_signature = my_manager.cancel_appointment(cancellation_json)
  File "/usr/local/Cellar/python@3.8/3.8.12_1/Frameworks/Python.framework/Versions/3.8/lib/python3.8/unittest/case.py", line 227, in __exit__
    self._raiseFailure("{} not raised".format(exc_name))
  File "/usr/local/Cellar/python@3.8/3.8.12_1/Frameworks/Python.framework/Versions/3.8/lib/python3.8/unittest/case.py", line 164, in _raiseFailure
    raise self.test_case.failureException(msg)
AssertionError: VaccineManagementException not raised
]]></failure>
	</testcase>
	<testcase classname="test_cancellation_tests.TestCancellation" name="test_parametrized_Json_Case_NV (test='Case_NV_19')" time="0.000" timestamp="0001-01-01T00:00:00">
		<failure type="AssertionError" message="VaccineManagementException not raised"><![CDATA[Traceback (most recent call last):
  File "/usr/local/Cellar/python@3.8/3.8.12_1/Frameworks/Python.framework/Versions/3.8/lib/python3.8/unittest/case.py", line 60, in testPartExecutor
    yield
  File "/usr/local/Cellar/python@3.8/3.8.12_1/Frameworks/Python.framework/Versions/3.8/lib/python3.8/unittest/case.py", line 582, in subTest
    yield
  File "/Users/aaron/PycharmProjects/G89.2022.T21.FP/src/unittest/python/test_cancellation_tests.py", line 219, in test_parametrized_Json_Case_NV
    date_signature = my_manager.cancel_appointment(cancellation_json)
  File "/usr/local/Cellar/python@3.8/3.8.12_1/Frameworks/Python.framework/Versions/3.8/lib/python3.8/unittest/case.py", line 227, in __exit__
    self._raiseFailure("{} not raised".format(exc_name))
  File "/usr/local/Cellar/python@3.8/3.8.12_1/Frameworks/Python.framework/Versions/3.8/lib/python3.8/unittest/case.py", line 164, in _raiseFailure
    raise self.test_case.failureException(msg)
AssertionError: VaccineManagementException not raised
]]></failure>
	</testcase>
	<testcase classname="test_cancellation_tests.TestCancellation" name="test_parametrized_Json_Case_NV (test='Case_NV_20')" time="0.000" timestamp="0001-01-01T00:00:00">
		<failure type="AssertionError" message="VaccineManagementException not raised"><![CDATA[Traceback (most recent call last):
  File "/usr/local/Cellar/python@3.8/3.8.12_1/Frameworks/Python.framework/Versions/3.8/lib/python3.8/unittest/case.py", line 60, in testPartExecutor
    yield
  File "/usr/local/Cellar/python@3.8/3.8.12_1/Frameworks/Python.framework/Versions/3.8/lib/python3.8/unittest/case.py", line 582, in subTest
    yield
  File "/Users/aaron/PycharmProjects/G89.2022.T21.FP/src/unittest/python/test_cancellation_tests.py", line 219, in test_parametrized_Json_Case_NV
    date_signature = my_manager.cancel_appointment(cancellation_json)
  File "/usr/local/Cellar/python@3.8/3.8.12_1/Frameworks/Python.framework/Versions/3.8/lib/python3.8/unittest/case.py", line 227, in __exit__
    self._raiseFailure("{} not raised".format(exc_name))
  File "/usr/local/Cellar/python@3.8/3.8.12_1/Frameworks/Python.framework/Versions/3.8/lib/python3.8/unittest/case.py", line 164, in _raiseFailure
    raise self.test_case.failureException(msg)
AssertionError: VaccineManagementException not raised
]]></failure>
	</testcase>
	<testcase classname="test_cancellation_tests.TestCancellation" name="test_parametrized_Json_Case_NV (test='Case_NV_21')" time="0.000" timestamp="0001-01-01T00:00:00">
		<failure type="AssertionError" message="VaccineManagementException not raised"><![CDATA[Traceback (most recent call last):
  File "/usr/local/Cellar/python@3.8/3.8.12_1/Frameworks/Python.framework/Versions/3.8/lib/python3.8/unittest/case.py", line 60, in testPartExecutor
    yield
  File "/usr/local/Cellar/python@3.8/3.8.12_1/Frameworks/Python.framework/Versions/3.8/lib/python3.8/unittest/case.py", line 582, in subTest
    yield
  File "/Users/aaron/PycharmProjects/G89.2022.T21.FP/src/unittest/python/test_cancellation_tests.py", line 219, in test_parametrized_Json_Case_NV
    date_signature = my_manager.cancel_appointment(cancellation_json)
  File "/usr/local/Cellar/python@3.8/3.8.12_1/Frameworks/Python.framework/Versions/3.8/lib/python3.8/unittest/case.py", line 227, in __exit__
    self._raiseFailure("{} not raised".format(exc_name))
  File "/usr/local/Cellar/python@3.8/3.8.12_1/Frameworks/Python.framework/Versions/3.8/lib/python3.8/unittest/case.py", line 164, in _raiseFailure
    raise self.test_case.failureException(msg)
AssertionError: VaccineManagementException not raised
]]></failure>
	</testcase>
	<testcase classname="test_cancellation_tests.TestCancellation" name="test_parametrized_Json_Case_NV (test='Case_NV_22')" time="0.000" timestamp="0001-01-01T00:00:00">
		<failure type="AssertionError" message="VaccineManagementException not raised"><![CDATA[Traceback (most recent call last):
  File "/usr/local/Cellar/python@3.8/3.8.12_1/Frameworks/Python.framework/Versions/3.8/lib/python3.8/unittest/case.py", line 60, in testPartExecutor
    yield
  File "/usr/local/Cellar/python@3.8/3.8.12_1/Frameworks/Python.framework/Versions/3.8/lib/python3.8/unittest/case.py", line 582, in subTest
    yield
  File "/Users/aaron/PycharmProjects/G89.2022.T21.FP/src/unittest/python/test_cancellation_tests.py", line 219, in test_parametrized_Json_Case_NV
    date_signature = my_manager.cancel_appointment(cancellation_json)
  File "/usr/local/Cellar/python@3.8/3.8.12_1/Frameworks/Python.framework/Versions/3.8/lib/python3.8/unittest/case.py", line 227, in __exit__
    self._raiseFailure("{} not raised".format(exc_name))
  File "/usr/local/Cellar/python@3.8/3.8.12_1/Frameworks/Python.framework/Versions/3.8/lib/python3.8/unittest/case.py", line 164, in _raiseFailure
    raise self.test_case.failureException(msg)
AssertionError: VaccineManagementException not raised
]]></failure>
	</testcase>
	<testcase classname="test_cancellation_tests.TestCancellation" name="test_parametrized_Json_Case_NV (test='Case_NV_23')" time="0.000" timestamp="0001-01-01T00:00:00">
		<failure type="AssertionError" message="VaccineManagementException not raised"><![CDATA[Traceback (most recent call last):
  File "/usr/local/Cellar/python@3.8/3.8.12_1/Frameworks/Python.framework/Versions/3.8/lib/python3.8/unittest/case.py", line 60, in testPartExecutor
    yield
  File "/usr/local/Cellar/python@3.8/3.8.12_1/Frameworks/Python.framework/Versions/3.8/lib/python3.8/unittest/case.py", line 582, in subTest
    yield
  File "/Users/aaron/PycharmProjects/G89.2022.T21.FP/src/unittest/python/test_cancellation_tests.py", line 219, in test_parametrized_Json_Case_NV
    date_signature = my_manager.cancel_appointment(cancellation_json)
  File "/usr/local/Cellar/python@3.8/3.8.12_1/Frameworks/Python.framework/Versions/3.8/lib/python3.8/unittest/case.py", line 227, in __exit__
    self._raiseFailure("{} not raised".format(exc_name))
  File "/usr/local/Cellar/python@3.8/3.8.12_1/Frameworks/Python.framework/Versions/3.8/lib/python3.8/unittest/case.py", line 164, in _raiseFailure
    raise self.test_case.failureException(msg)
AssertionError: VaccineManagementException not raised
]]></failure>
	</testcase>
	<testcase classname="test_cancellation_tests.TestCancellation" name="test_parametrized_Json_Case_NV (test='Case_NV_24')" time="0.000" timestamp="0001-01-01T00:00:00">
		<failure type="AssertionError" message="VaccineManagementException not raised"><![CDATA[Traceback (most recent call last):
  File "/usr/local/Cellar/python@3.8/3.8.12_1/Frameworks/Python.framework/Versions/3.8/lib/python3.8/unittest/case.py", line 60, in testPartExecutor
    yield
  File "/usr/local/Cellar/python@3.8/3.8.12_1/Frameworks/Python.framework/Versions/3.8/lib/python3.8/unittest/case.py", line 582, in subTest
    yield
  File "/Users/aaron/PycharmProjects/G89.2022.T21.FP/src/unittest/python/test_cancellation_tests.py", line 219, in test_parametrized_Json_Case_NV
    date_signature = my_manager.cancel_appointment(cancellation_json)
  File "/usr/local/Cellar/python@3.8/3.8.12_1/Frameworks/Python.framework/Versions/3.8/lib/python3.8/unittest/case.py", line 227, in __exit__
    self._raiseFailure("{} not raised".format(exc_name))
  File "/usr/local/Cellar/python@3.8/3.8.12_1/Frameworks/Python.framework/Versions/3.8/lib/python3.8/unittest/case.py", line 164, in _raiseFailure
    raise self.test_case.failureException(msg)
AssertionError: VaccineManagementException not raised
]]></failure>
	</testcase>
	<testcase classname="test_cancellation_tests.TestCancellation" name="test_parametrized_Json_Case_NV (test='Case_NV_25')" time="0.000" timestamp="0001-01-01T00:00:00">
		<failure type="AssertionError" message="VaccineManagementException not raised"><![CDATA[Traceback (most recent call last):
  File "/usr/local/Cellar/python@3.8/3.8.12_1/Frameworks/Python.framework/Versions/3.8/lib/python3.8/unittest/case.py", line 60, in testPartExecutor
    yield
  File "/usr/local/Cellar/python@3.8/3.8.12_1/Frameworks/Python.framework/Versions/3.8/lib/python3.8/unittest/case.py", line 582, in subTest
    yield
  File "/Users/aaron/PycharmProjects/G89.2022.T21.FP/src/unittest/python/test_cancellation_tests.py", line 219, in test_parametrized_Json_Case_NV
    date_signature = my_manager.cancel_appointment(cancellation_json)
  File "/usr/local/Cellar/python@3.8/3.8.12_1/Frameworks/Python.framework/Versions/3.8/lib/python3.8/unittest/case.py", line 227, in __exit__
    self._raiseFailure("{} not raised".format(exc_name))
  File "/usr/local/Cellar/python@3.8/3.8.12_1/Frameworks/Python.framework/Versions/3.8/lib/python3.8/unittest/case.py", line 164, in _raiseFailure
    raise self.test_case.failureException(msg)
AssertionError: VaccineManagementException not raised
]]></failure>
	</testcase>
	<testcase classname="test_cancellation_tests.TestCancellation" name="test_parametrized_Json_Case_NV (test='Case_NV_26')" time="0.000" timestamp="0001-01-01T00:00:00">
		<failure type="AssertionError" message="VaccineManagementException not raised"><![CDATA[Traceback (most recent call last):
  File "/usr/local/Cellar/python@3.8/3.8.12_1/Frameworks/Python.framework/Versions/3.8/lib/python3.8/unittest/case.py", line 60, in testPartExecutor
    yield
  File "/usr/local/Cellar/python@3.8/3.8.12_1/Frameworks/Python.framework/Versions/3.8/lib/python3.8/unittest/case.py", line 582, in subTest
    yield
  File "/Users/aaron/PycharmProjects/G89.2022.T21.FP/src/unittest/python/test_cancellation_tests.py", line 219, in test_parametrized_Json_Case_NV
    date_signature = my_manager.cancel_appointment(cancellation_json)
  File "/usr/local/Cellar/python@3.8/3.8.12_1/Frameworks/Python.framework/Versions/3.8/lib/python3.8/unittest/case.py", line 227, in __exit__
    self._raiseFailure("{} not raised".format(exc_name))
  File "/usr/local/Cellar/python@3.8/3.8.12_1/Frameworks/Python.framework/Versions/3.8/lib/python3.8/unittest/case.py", line 164, in _raiseFailure
    raise self.test_case.failureException(msg)
AssertionError: VaccineManagementException not raised
]]></failure>
	</testcase>
	<testcase classname="test_cancellation_tests.TestCancellation" name="test_parametrized_Json_Case_NV (test='Case_NV_27')" time="0.000" timestamp="0001-01-01T00:00:00">
		<failure type="AssertionError" message="VaccineManagementException not raised"><![CDATA[Traceback (most recent call last):
  File "/usr/local/Cellar/python@3.8/3.8.12_1/Frameworks/Python.framework/Versions/3.8/lib/python3.8/unittest/case.py", line 60, in testPartExecutor
    yield
  File "/usr/local/Cellar/python@3.8/3.8.12_1/Frameworks/Python.framework/Versions/3.8/lib/python3.8/unittest/case.py", line 582, in subTest
    yield
  File "/Users/aaron/PycharmProjects/G89.2022.T21.FP/src/unittest/python/test_cancellation_tests.py", line 219, in test_parametrized_Json_Case_NV
    date_signature = my_manager.cancel_appointment(cancellation_json)
  File "/usr/local/Cellar/python@3.8/3.8.12_1/Frameworks/Python.framework/Versions/3.8/lib/python3.8/unittest/case.py", line 227, in __exit__
    self._raiseFailure("{} not raised".format(exc_name))
  File "/usr/local/Cellar/python@3.8/3.8.12_1/Frameworks/Python.framework/Versions/3.8/lib/python3.8/unittest/case.py", line 164, in _raiseFailure
    raise self.test_case.failureException(msg)
AssertionError: VaccineManagementException not raised
]]></failure>
	</testcase>
	<testcase classname="test_cancellation_tests.TestCancellation" name="test_parametrized_Json_Case_NV (test='Case_NV_28')" time="0.000" timestamp="0001-01-01T00:00:00">
		<failure type="AssertionError" message="VaccineManagementException not raised"><![CDATA[Traceback (most recent call last):
  File "/usr/local/Cellar/python@3.8/3.8.12_1/Frameworks/Python.framework/Versions/3.8/lib/python3.8/unittest/case.py", line 60, in testPartExecutor
    yield
  File "/usr/local/Cellar/python@3.8/3.8.12_1/Frameworks/Python.framework/Versions/3.8/lib/python3.8/unittest/case.py", line 582, in subTest
    yield
  File "/Users/aaron/PycharmProjects/G89.2022.T21.FP/src/unittest/python/test_cancellation_tests.py", line 219, in test_parametrized_Json_Case_NV
    date_signature = my_manager.cancel_appointment(cancellation_json)
  File "/usr/local/Cellar/python@3.8/3.8.12_1/Frameworks/Python.framework/Versions/3.8/lib/python3.8/unittest/case.py", line 227, in __exit__
    self._raiseFailure("{} not raised".format(exc_name))
  File "/usr/local/Cellar/python@3.8/3.8.12_1/Frameworks/Python.framework/Versions/3.8/lib/python3.8/unittest/case.py", line 164, in _raiseFailure
    raise self.test_case.failureException(msg)
AssertionError: VaccineManagementException not raised
]]></failure>
	</testcase>
	<testcase classname="test_cancellation_tests.TestCancellation" name="test_parametrized_Json_Case_NV (test='Case_NV_29')" time="0.000" timestamp="0001-01-01T00:00:00">
		<failure type="AssertionError" message="VaccineManagementException not raised"><![CDATA[Traceback (most recent call last):
  File "/usr/local/Cellar/python@3.8/3.8.12_1/Frameworks/Python.framework/Versions/3.8/lib/python3.8/unittest/case.py", line 60, in testPartExecutor
    yield
  File "/usr/local/Cellar/python@3.8/3.8.12_1/Frameworks/Python.framework/Versions/3.8/lib/python3.8/unittest/case.py", line 582, in subTest
    yield
  File "/Users/aaron/PycharmProjects/G89.2022.T21.FP/src/unittest/python/test_cancellation_tests.py", line 219, in test_parametrized_Json_Case_NV
    date_signature = my_manager.cancel_appointment(cancellation_json)
  File "/usr/local/Cellar/python@3.8/3.8.12_1/Frameworks/Python.framework/Versions/3.8/lib/python3.8/unittest/case.py", line 227, in __exit__
    self._raiseFailure("{} not raised".format(exc_name))
  File "/usr/local/Cellar/python@3.8/3.8.12_1/Frameworks/Python.framework/Versions/3.8/lib/python3.8/unittest/case.py", line 164, in _raiseFailure
    raise self.test_case.failureException(msg)
AssertionError: VaccineManagementException not raised
]]></failure>
	</testcase>
	<testcase classname="test_cancellation_tests.TestCancellation" name="test_parametrized_Json_Case_NV (test='Case_NV_30')" time="0.000" timestamp="0001-01-01T00:00:00">
		<failure type="AssertionError" message="VaccineManagementException not raised"><![CDATA[Traceback (most recent call last):
  File "/usr/local/Cellar/python@3.8/3.8.12_1/Frameworks/Python.framework/Versions/3.8/lib/python3.8/unittest/case.py", line 60, in testPartExecutor
    yield
  File "/usr/local/Cellar/python@3.8/3.8.12_1/Frameworks/Python.framework/Versions/3.8/lib/python3.8/unittest/case.py", line 582, in subTest
    yield
  File "/Users/aaron/PycharmProjects/G89.2022.T21.FP/src/unittest/python/test_cancellation_tests.py", line 219, in test_parametrized_Json_Case_NV
    date_signature = my_manager.cancel_appointment(cancellation_json)
  File "/usr/local/Cellar/python@3.8/3.8.12_1/Frameworks/Python.framework/Versions/3.8/lib/python3.8/unittest/case.py", line 227, in __exit__
    self._raiseFailure("{} not raised".format(exc_name))
  File "/usr/local/Cellar/python@3.8/3.8.12_1/Frameworks/Python.framework/Versions/3.8/lib/python3.8/unittest/case.py", line 164, in _raiseFailure
    raise self.test_case.failureException(msg)
AssertionError: VaccineManagementException not raised
]]></failure>
	</testcase>
	<testcase classname="test_cancellation_tests.TestCancellation" name="test_parametrized_Json_Case_NV (test='Case_NV_31')" time="0.000" timestamp="0001-01-01T00:00:00">
		<failure type="AssertionError" message="VaccineManagementException not raised"><![CDATA[Traceback (most recent call last):
  File "/usr/local/Cellar/python@3.8/3.8.12_1/Frameworks/Python.framework/Versions/3.8/lib/python3.8/unittest/case.py", line 60, in testPartExecutor
    yield
  File "/usr/local/Cellar/python@3.8/3.8.12_1/Frameworks/Python.framework/Versions/3.8/lib/python3.8/unittest/case.py", line 582, in subTest
    yield
  File "/Users/aaron/PycharmProjects/G89.2022.T21.FP/src/unittest/python/test_cancellation_tests.py", line 219, in test_parametrized_Json_Case_NV
    date_signature = my_manager.cancel_appointment(cancellation_json)
  File "/usr/local/Cellar/python@3.8/3.8.12_1/Frameworks/Python.framework/Versions/3.8/lib/python3.8/unittest/case.py", line 227, in __exit__
    self._raiseFailure("{} not raised".format(exc_name))
  File "/usr/local/Cellar/python@3.8/3.8.12_1/Frameworks/Python.framework/Versions/3.8/lib/python3.8/unittest/case.py", line 164, in _raiseFailure
    raise self.test_case.failureException(msg)
AssertionError: VaccineManagementException not raised
]]></failure>
	</testcase>
	<testcase classname="test_cancellation_tests.TestCancellation" name="test_parametrized_Json_Case_NV (test='Case_NV_32')" time="0.000" timestamp="0001-01-01T00:00:00">
		<failure type="AssertionError" message="VaccineManagementException not raised"><![CDATA[Traceback (most recent call last):
  File "/usr/local/Cellar/python@3.8/3.8.12_1/Frameworks/Python.framework/Versions/3.8/lib/python3.8/unittest/case.py", line 60, in testPartExecutor
    yield
  File "/usr/local/Cellar/python@3.8/3.8.12_1/Frameworks/Python.framework/Versions/3.8/lib/python3.8/unittest/case.py", line 582, in subTest
    yield
  File "/Users/aaron/PycharmProjects/G89.2022.T21.FP/src/unittest/python/test_cancellation_tests.py", line 219, in test_parametrized_Json_Case_NV
    date_signature = my_manager.cancel_appointment(cancellation_json)
  File "/usr/local/Cellar/python@3.8/3.8.12_1/Frameworks/Python.framework/Versions/3.8/lib/python3.8/unittest/case.py", line 227, in __exit__
    self._raiseFailure("{} not raised".format(exc_name))
  File "/usr/local/Cellar/python@3.8/3.8.12_1/Frameworks/Python.framework/Versions/3.8/lib/python3.8/unittest/case.py", line 164, in _raiseFailure
    raise self.test_case.failureException(msg)
AssertionError: VaccineManagementException not raised
]]></failure>
	</testcase>
	<testcase classname="test_cancellation_tests.TestCancellation" name="test_parametrized_Json_Case_NV (test='Case_NV_33')" time="0.000" timestamp="0001-01-01T00:00:00">
		<failure type="AssertionError" message="VaccineManagementException not raised"><![CDATA[Traceback (most recent call last):
  File "/usr/local/Cellar/python@3.8/3.8.12_1/Frameworks/Python.framework/Versions/3.8/lib/python3.8/unittest/case.py", line 60, in testPartExecutor
    yield
  File "/usr/local/Cellar/python@3.8/3.8.12_1/Frameworks/Python.framework/Versions/3.8/lib/python3.8/unittest/case.py", line 582, in subTest
    yield
  File "/Users/aaron/PycharmProjects/G89.2022.T21.FP/src/unittest/python/test_cancellation_tests.py", line 219, in test_parametrized_Json_Case_NV
    date_signature = my_manager.cancel_appointment(cancellation_json)
  File "/usr/local/Cellar/python@3.8/3.8.12_1/Frameworks/Python.framework/Versions/3.8/lib/python3.8/unittest/case.py", line 227, in __exit__
    self._raiseFailure("{} not raised".format(exc_name))
  File "/usr/local/Cellar/python@3.8/3.8.12_1/Frameworks/Python.framework/Versions/3.8/lib/python3.8/unittest/case.py", line 164, in _raiseFailure
    raise self.test_case.failureException(msg)
AssertionError: VaccineManagementException not raised
]]></failure>
	</testcase>
	<testcase classname="test_cancellation_tests.TestCancellation" name="test_parametrized_Json_Case_NV (test='Case_NV_34')" time="0.000" timestamp="0001-01-01T00:00:00">
		<failure type="AssertionError" message="VaccineManagementException not raised"><![CDATA[Traceback (most recent call last):
  File "/usr/local/Cellar/python@3.8/3.8.12_1/Frameworks/Python.framework/Versions/3.8/lib/python3.8/unittest/case.py", line 60, in testPartExecutor
    yield
  File "/usr/local/Cellar/python@3.8/3.8.12_1/Frameworks/Python.framework/Versions/3.8/lib/python3.8/unittest/case.py", line 582, in subTest
    yield
  File "/Users/aaron/PycharmProjects/G89.2022.T21.FP/src/unittest/python/test_cancellation_tests.py", line 219, in test_parametrized_Json_Case_NV
    date_signature = my_manager.cancel_appointment(cancellation_json)
  File "/usr/local/Cellar/python@3.8/3.8.12_1/Frameworks/Python.framework/Versions/3.8/lib/python3.8/unittest/case.py", line 227, in __exit__
    self._raiseFailure("{} not raised".format(exc_name))
  File "/usr/local/Cellar/python@3.8/3.8.12_1/Frameworks/Python.framework/Versions/3.8/lib/python3.8/unittest/case.py", line 164, in _raiseFailure
    raise self.test_case.failureException(msg)
AssertionError: VaccineManagementException not raised
]]></failure>
	</testcase>
	<testcase classname="test_cancellation_tests.TestCancellation" name="test_parametrized_Json_Case_NV (test='Case_NV_35')" time="0.000" timestamp="0001-01-01T00:00:00">
		<failure type="AssertionError" message="VaccineManagementException not raised"><![CDATA[Traceback (most recent call last):
  File "/usr/local/Cellar/python@3.8/3.8.12_1/Frameworks/Python.framework/Versions/3.8/lib/python3.8/unittest/case.py", line 60, in testPartExecutor
    yield
  File "/usr/local/Cellar/python@3.8/3.8.12_1/Frameworks/Python.framework/Versions/3.8/lib/python3.8/unittest/case.py", line 582, in subTest
    yield
  File "/Users/aaron/PycharmProjects/G89.2022.T21.FP/src/unittest/python/test_cancellation_tests.py", line 219, in test_parametrized_Json_Case_NV
    date_signature = my_manager.cancel_appointment(cancellation_json)
  File "/usr/local/Cellar/python@3.8/3.8.12_1/Frameworks/Python.framework/Versions/3.8/lib/python3.8/unittest/case.py", line 227, in __exit__
    self._raiseFailure("{} not raised".format(exc_name))
  File "/usr/local/Cellar/python@3.8/3.8.12_1/Frameworks/Python.framework/Versions/3.8/lib/python3.8/unittest/case.py", line 164, in _raiseFailure
    raise self.test_case.failureException(msg)
AssertionError: VaccineManagementException not raised
]]></failure>
	</testcase>
	<testcase classname="test_cancellation_tests.TestCancellation" name="test_parametrized_Json_Case_NV (test='Case_NV_36')" time="0.000" timestamp="0001-01-01T00:00:00">
		<failure type="AssertionError" message="VaccineManagementException not raised"><![CDATA[Traceback (most recent call last):
  File "/usr/local/Cellar/python@3.8/3.8.12_1/Frameworks/Python.framework/Versions/3.8/lib/python3.8/unittest/case.py", line 60, in testPartExecutor
    yield
  File "/usr/local/Cellar/python@3.8/3.8.12_1/Frameworks/Python.framework/Versions/3.8/lib/python3.8/unittest/case.py", line 582, in subTest
    yield
  File "/Users/aaron/PycharmProjects/G89.2022.T21.FP/src/unittest/python/test_cancellation_tests.py", line 219, in test_parametrized_Json_Case_NV
    date_signature = my_manager.cancel_appointment(cancellation_json)
  File "/usr/local/Cellar/python@3.8/3.8.12_1/Frameworks/Python.framework/Versions/3.8/lib/python3.8/unittest/case.py", line 227, in __exit__
    self._raiseFailure("{} not raised".format(exc_name))
  File "/usr/local/Cellar/python@3.8/3.8.12_1/Frameworks/Python.framework/Versions/3.8/lib/python3.8/unittest/case.py", line 164, in _raiseFailure
    raise self.test_case.failureException(msg)
AssertionError: VaccineManagementException not raised
]]></failure>
	</testcase>
	<testcase classname="test_cancellation_tests.TestCancellation" name="test_parametrized_Json_Case_NV (test='Case_NV_37')" time="0.000" timestamp="0001-01-01T00:00:00">
		<failure type="AssertionError" message="VaccineManagementException not raised"><![CDATA[Traceback (most recent call last):
  File "/usr/local/Cellar/python@3.8/3.8.12_1/Frameworks/Python.framework/Versions/3.8/lib/python3.8/unittest/case.py", line 60, in testPartExecutor
    yield
  File "/usr/local/Cellar/python@3.8/3.8.12_1/Frameworks/Python.framework/Versions/3.8/lib/python3.8/unittest/case.py", line 582, in subTest
    yield
  File "/Users/aaron/PycharmProjects/G89.2022.T21.FP/src/unittest/python/test_cancellation_tests.py", line 219, in test_parametrized_Json_Case_NV
    date_signature = my_manager.cancel_appointment(cancellation_json)
  File "/usr/local/Cellar/python@3.8/3.8.12_1/Frameworks/Python.framework/Versions/3.8/lib/python3.8/unittest/case.py", line 227, in __exit__
    self._raiseFailure("{} not raised".format(exc_name))
  File "/usr/local/Cellar/python@3.8/3.8.12_1/Frameworks/Python.framework/Versions/3.8/lib/python3.8/unittest/case.py", line 164, in _raiseFailure
    raise self.test_case.failureException(msg)
AssertionError: VaccineManagementException not raised
]]></failure>
	</testcase>
	<testcase classname="test_cancellation_tests.TestCancellation" name="test_parametrized_Json_Case_NV (test='Case_NV_38')" time="0.000" timestamp="0001-01-01T00:00:00">
		<failure type="AssertionError" message="VaccineManagementException not raised"><![CDATA[Traceback (most recent call last):
  File "/usr/local/Cellar/python@3.8/3.8.12_1/Frameworks/Python.framework/Versions/3.8/lib/python3.8/unittest/case.py", line 60, in testPartExecutor
    yield
  File "/usr/local/Cellar/python@3.8/3.8.12_1/Frameworks/Python.framework/Versions/3.8/lib/python3.8/unittest/case.py", line 582, in subTest
    yield
  File "/Users/aaron/PycharmProjects/G89.2022.T21.FP/src/unittest/python/test_cancellation_tests.py", line 219, in test_parametrized_Json_Case_NV
    date_signature = my_manager.cancel_appointment(cancellation_json)
  File "/usr/local/Cellar/python@3.8/3.8.12_1/Frameworks/Python.framework/Versions/3.8/lib/python3.8/unittest/case.py", line 227, in __exit__
    self._raiseFailure("{} not raised".format(exc_name))
  File "/usr/local/Cellar/python@3.8/3.8.12_1/Frameworks/Python.framework/Versions/3.8/lib/python3.8/unittest/case.py", line 164, in _raiseFailure
    raise self.test_case.failureException(msg)
AssertionError: VaccineManagementException not raised
]]></failure>
	</testcase>
	<testcase classname="test_cancellation_tests.TestCancellation" name="test_parametrized_Json_Case_NV (test='Case_NV_39')" time="0.000" timestamp="0001-01-01T00:00:00">
		<failure type="AssertionError" message="VaccineManagementException not raised"><![CDATA[Traceback (most recent call last):
  File "/usr/local/Cellar/python@3.8/3.8.12_1/Frameworks/Python.framework/Versions/3.8/lib/python3.8/unittest/case.py", line 60, in testPartExecutor
    yield
  File "/usr/local/Cellar/python@3.8/3.8.12_1/Frameworks/Python.framework/Versions/3.8/lib/python3.8/unittest/case.py", line 582, in subTest
    yield
  File "/Users/aaron/PycharmProjects/G89.2022.T21.FP/src/unittest/python/test_cancellation_tests.py", line 219, in test_parametrized_Json_Case_NV
    date_signature = my_manager.cancel_appointment(cancellation_json)
  File "/usr/local/Cellar/python@3.8/3.8.12_1/Frameworks/Python.framework/Versions/3.8/lib/python3.8/unittest/case.py", line 227, in __exit__
    self._raiseFailure("{} not raised".format(exc_name))
  File "/usr/local/Cellar/python@3.8/3.8.12_1/Frameworks/Python.framework/Versions/3.8/lib/python3.8/unittest/case.py", line 164, in _raiseFailure
    raise self.test_case.failureException(msg)
AssertionError: VaccineManagementException not raised
]]></failure>
	</testcase>
	<testcase classname="test_cancellation_tests.TestCancellation" name="test_parametrized_Json_Case_NV (test='Case_NV_40')" time="0.000" timestamp="0001-01-01T00:00:00">
		<failure type="AssertionError" message="VaccineManagementException not raised"><![CDATA[Traceback (most recent call last):
  File "/usr/local/Cellar/python@3.8/3.8.12_1/Frameworks/Python.framework/Versions/3.8/lib/python3.8/unittest/case.py", line 60, in testPartExecutor
    yield
  File "/usr/local/Cellar/python@3.8/3.8.12_1/Frameworks/Python.framework/Versions/3.8/lib/python3.8/unittest/case.py", line 582, in subTest
    yield
  File "/Users/aaron/PycharmProjects/G89.2022.T21.FP/src/unittest/python/test_cancellation_tests.py", line 219, in test_parametrized_Json_Case_NV
    date_signature = my_manager.cancel_appointment(cancellation_json)
  File "/usr/local/Cellar/python@3.8/3.8.12_1/Frameworks/Python.framework/Versions/3.8/lib/python3.8/unittest/case.py", line 227, in __exit__
    self._raiseFailure("{} not raised".format(exc_name))
  File "/usr/local/Cellar/python@3.8/3.8.12_1/Frameworks/Python.framework/Versions/3.8/lib/python3.8/unittest/case.py", line 164, in _raiseFailure
    raise self.test_case.failureException(msg)
AssertionError: VaccineManagementException not raised
]]></failure>
	</testcase>
	<testcase classname="test_cancellation_tests.TestCancellation" name="test_parametrized_Json_Case_NV (test='Case_NV_41')" time="0.000" timestamp="0001-01-01T00:00:00">
		<failure type="AssertionError" message="VaccineManagementException not raised"><![CDATA[Traceback (most recent call last):
  File "/usr/local/Cellar/python@3.8/3.8.12_1/Frameworks/Python.framework/Versions/3.8/lib/python3.8/unittest/case.py", line 60, in testPartExecutor
    yield
  File "/usr/local/Cellar/python@3.8/3.8.12_1/Frameworks/Python.framework/Versions/3.8/lib/python3.8/unittest/case.py", line 582, in subTest
    yield
  File "/Users/aaron/PycharmProjects/G89.2022.T21.FP/src/unittest/python/test_cancellation_tests.py", line 219, in test_parametrized_Json_Case_NV
    date_signature = my_manager.cancel_appointment(cancellation_json)
  File "/usr/local/Cellar/python@3.8/3.8.12_1/Frameworks/Python.framework/Versions/3.8/lib/python3.8/unittest/case.py", line 227, in __exit__
    self._raiseFailure("{} not raised".format(exc_name))
  File "/usr/local/Cellar/python@3.8/3.8.12_1/Frameworks/Python.framework/Versions/3.8/lib/python3.8/unittest/case.py", line 164, in _raiseFailure
    raise self.test_case.failureException(msg)
AssertionError: VaccineManagementException not raised
]]></failure>
	</testcase>
	<testcase classname="test_cancellation_tests.TestCancellation" name="test_parametrized_Json_Case_NV (test='Case_NV_42')" time="0.000" timestamp="0001-01-01T00:00:00">
		<failure type="AssertionError" message="VaccineManagementException not raised"><![CDATA[Traceback (most recent call last):
  File "/usr/local/Cellar/python@3.8/3.8.12_1/Frameworks/Python.framework/Versions/3.8/lib/python3.8/unittest/case.py", line 60, in testPartExecutor
    yield
  File "/usr/local/Cellar/python@3.8/3.8.12_1/Frameworks/Python.framework/Versions/3.8/lib/python3.8/unittest/case.py", line 582, in subTest
    yield
  File "/Users/aaron/PycharmProjects/G89.2022.T21.FP/src/unittest/python/test_cancellation_tests.py", line 219, in test_parametrized_Json_Case_NV
    date_signature = my_manager.cancel_appointment(cancellation_json)
  File "/usr/local/Cellar/python@3.8/3.8.12_1/Frameworks/Python.framework/Versions/3.8/lib/python3.8/unittest/case.py", line 227, in __exit__
    self._raiseFailure("{} not raised".format(exc_name))
  File "/usr/local/Cellar/python@3.8/3.8.12_1/Frameworks/Python.framework/Versions/3.8/lib/python3.8/unittest/case.py", line 164, in _raiseFailure
    raise self.test_case.failureException(msg)
AssertionError: VaccineManagementException not raised
]]></failure>
	</testcase>
	<testcase classname="test_cancellation_tests.TestCancellation" name="test_parametrized_Json_Case_NV (test='Case_NV_43')" time="0.000" timestamp="0001-01-01T00:00:00">
		<failure type="AssertionError" message="VaccineManagementException not raised"><![CDATA[Traceback (most recent call last):
  File "/usr/local/Cellar/python@3.8/3.8.12_1/Frameworks/Python.framework/Versions/3.8/lib/python3.8/unittest/case.py", line 60, in testPartExecutor
    yield
  File "/usr/local/Cellar/python@3.8/3.8.12_1/Frameworks/Python.framework/Versions/3.8/lib/python3.8/unittest/case.py", line 582, in subTest
    yield
  File "/Users/aaron/PycharmProjects/G89.2022.T21.FP/src/unittest/python/test_cancellation_tests.py", line 219, in test_parametrized_Json_Case_NV
    date_signature = my_manager.cancel_appointment(cancellation_json)
  File "/usr/local/Cellar/python@3.8/3.8.12_1/Frameworks/Python.framework/Versions/3.8/lib/python3.8/unittest/case.py", line 227, in __exit__
    self._raiseFailure("{} not raised".format(exc_name))
  File "/usr/local/Cellar/python@3.8/3.8.12_1/Frameworks/Python.framework/Versions/3.8/lib/python3.8/unittest/case.py", line 164, in _raiseFailure
    raise self.test_case.failureException(msg)
AssertionError: VaccineManagementException not raised
]]></failure>
	</testcase>
	<testcase classname="test_cancellation_tests.TestCancellation" name="test_parametrized_Json_Case_NV (test='Case_NV_44')" time="0.000" timestamp="0001-01-01T00:00:00">
		<failure type="AssertionError" message="VaccineManagementException not raised"><![CDATA[Traceback (most recent call last):
  File "/usr/local/Cellar/python@3.8/3.8.12_1/Frameworks/Python.framework/Versions/3.8/lib/python3.8/unittest/case.py", line 60, in testPartExecutor
    yield
  File "/usr/local/Cellar/python@3.8/3.8.12_1/Frameworks/Python.framework/Versions/3.8/lib/python3.8/unittest/case.py", line 582, in subTest
    yield
  File "/Users/aaron/PycharmProjects/G89.2022.T21.FP/src/unittest/python/test_cancellation_tests.py", line 219, in test_parametrized_Json_Case_NV
    date_signature = my_manager.cancel_appointment(cancellation_json)
  File "/usr/local/Cellar/python@3.8/3.8.12_1/Frameworks/Python.framework/Versions/3.8/lib/python3.8/unittest/case.py", line 227, in __exit__
    self._raiseFailure("{} not raised".format(exc_name))
  File "/usr/local/Cellar/python@3.8/3.8.12_1/Frameworks/Python.framework/Versions/3.8/lib/python3.8/unittest/case.py", line 164, in _raiseFailure
    raise self.test_case.failureException(msg)
AssertionError: VaccineManagementException not raised
]]></failure>
	</testcase>
	<testcase classname="test_cancellation_tests.TestCancellation" name="test_parametrized_Json_Case_NV (test='Case_NV_45')" time="0.000" timestamp="0001-01-01T00:00:00">
		<failure type="AssertionError" message="VaccineManagementException not raised"><![CDATA[Traceback (most recent call last):
  File "/usr/local/Cellar/python@3.8/3.8.12_1/Frameworks/Python.framework/Versions/3.8/lib/python3.8/unittest/case.py", line 60, in testPartExecutor
    yield
  File "/usr/local/Cellar/python@3.8/3.8.12_1/Frameworks/Python.framework/Versions/3.8/lib/python3.8/unittest/case.py", line 582, in subTest
    yield
  File "/Users/aaron/PycharmProjects/G89.2022.T21.FP/src/unittest/python/test_cancellation_tests.py", line 219, in test_parametrized_Json_Case_NV
    date_signature = my_manager.cancel_appointment(cancellation_json)
  File "/usr/local/Cellar/python@3.8/3.8.12_1/Frameworks/Python.framework/Versions/3.8/lib/python3.8/unittest/case.py", line 227, in __exit__
    self._raiseFailure("{} not raised".format(exc_name))
  File "/usr/local/Cellar/python@3.8/3.8.12_1/Frameworks/Python.framework/Versions/3.8/lib/python3.8/unittest/case.py", line 164, in _raiseFailure
    raise self.test_case.failureException(msg)
AssertionError: VaccineManagementException not raised
]]></failure>
	</testcase>
	<testcase classname="test_cancellation_tests.TestCancellation" name="test_parametrized_Json_Case_NV (test='Case_NV_46')" time="0.000" timestamp="0001-01-01T00:00:00">
		<failure type="AssertionError" message="VaccineManagementException not raised"><![CDATA[Traceback (most recent call last):
  File "/usr/local/Cellar/python@3.8/3.8.12_1/Frameworks/Python.framework/Versions/3.8/lib/python3.8/unittest/case.py", line 60, in testPartExecutor
    yield
  File "/usr/local/Cellar/python@3.8/3.8.12_1/Frameworks/Python.framework/Versions/3.8/lib/python3.8/unittest/case.py", line 582, in subTest
    yield
  File "/Users/aaron/PycharmProjects/G89.2022.T21.FP/src/unittest/python/test_cancellation_tests.py", line 219, in test_parametrized_Json_Case_NV
    date_signature = my_manager.cancel_appointment(cancellation_json)
  File "/usr/local/Cellar/python@3.8/3.8.12_1/Frameworks/Python.framework/Versions/3.8/lib/python3.8/unittest/case.py", line 227, in __exit__
    self._raiseFailure("{} not raised".format(exc_name))
  File "/usr/local/Cellar/python@3.8/3.8.12_1/Frameworks/Python.framework/Versions/3.8/lib/python3.8/unittest/case.py", line 164, in _raiseFailure
    raise self.test_case.failureException(msg)
AssertionError: VaccineManagementException not raised
]]></failure>
	</testcase>
	<testcase classname="test_cancellation_tests.TestCancellation" name="test_parametrized_Json_Case_NV (test='Case_NV_47')" time="0.000" timestamp="0001-01-01T00:00:00">
		<failure type="AssertionError" message="VaccineManagementException not raised"><![CDATA[Traceback (most recent call last):
  File "/usr/local/Cellar/python@3.8/3.8.12_1/Frameworks/Python.framework/Versions/3.8/lib/python3.8/unittest/case.py", line 60, in testPartExecutor
    yield
  File "/usr/local/Cellar/python@3.8/3.8.12_1/Frameworks/Python.framework/Versions/3.8/lib/python3.8/unittest/case.py", line 582, in subTest
    yield
  File "/Users/aaron/PycharmProjects/G89.2022.T21.FP/src/unittest/python/test_cancellation_tests.py", line 219, in test_parametrized_Json_Case_NV
    date_signature = my_manager.cancel_appointment(cancellation_json)
  File "/usr/local/Cellar/python@3.8/3.8.12_1/Frameworks/Python.framework/Versions/3.8/lib/python3.8/unittest/case.py", line 227, in __exit__
    self._raiseFailure("{} not raised".format(exc_name))
  File "/usr/local/Cellar/python@3.8/3.8.12_1/Frameworks/Python.framework/Versions/3.8/lib/python3.8/unittest/case.py", line 164, in _raiseFailure
    raise self.test_case.failureException(msg)
AssertionError: VaccineManagementException not raised
]]></failure>
	</testcase>
	<testcase classname="test_cancellation_tests.TestCancellation" name="test_parametrized_Json_Case_NV (test='Case_NV_48')" time="0.000" timestamp="0001-01-01T00:00:00">
		<failure type="AssertionError" message="VaccineManagementException not raised"><![CDATA[Traceback (most recent call last):
  File "/usr/local/Cellar/python@3.8/3.8.12_1/Frameworks/Python.framework/Versions/3.8/lib/python3.8/unittest/case.py", line 60, in testPartExecutor
    yield
  File "/usr/local/Cellar/python@3.8/3.8.12_1/Frameworks/Python.framework/Versions/3.8/lib/python3.8/unittest/case.py", line 582, in subTest
    yield
  File "/Users/aaron/PycharmProjects/G89.2022.T21.FP/src/unittest/python/test_cancellation_tests.py", line 219, in test_parametrized_Json_Case_NV
    date_signature = my_manager.cancel_appointment(cancellation_json)
  File "/usr/local/Cellar/python@3.8/3.8.12_1/Frameworks/Python.framework/Versions/3.8/lib/python3.8/unittest/case.py", line 227, in __exit__
    self._raiseFailure("{} not raised".format(exc_name))
  File "/usr/local/Cellar/python@3.8/3.8.12_1/Frameworks/Python.framework/Versions/3.8/lib/python3.8/unittest/case.py", line 164, in _raiseFailure
    raise self.test_case.failureException(msg)
AssertionError: VaccineManagementException not raised
]]></failure>
	</testcase>
	<testcase classname="test_cancellation_tests.TestCancellation" name="test_parametrized_Json_Case_NV (test='Case_NV_49')" time="0.000" timestamp="0001-01-01T00:00:00">
		<failure type="AssertionError" message="VaccineManagementException not raised"><![CDATA[Traceback (most recent call last):
  File "/usr/local/Cellar/python@3.8/3.8.12_1/Frameworks/Python.framework/Versions/3.8/lib/python3.8/unittest/case.py", line 60, in testPartExecutor
    yield
  File "/usr/local/Cellar/python@3.8/3.8.12_1/Frameworks/Python.framework/Versions/3.8/lib/python3.8/unittest/case.py", line 582, in subTest
    yield
  File "/Users/aaron/PycharmProjects/G89.2022.T21.FP/src/unittest/python/test_cancellation_tests.py", line 219, in test_parametrized_Json_Case_NV
    date_signature = my_manager.cancel_appointment(cancellation_json)
  File "/usr/local/Cellar/python@3.8/3.8.12_1/Frameworks/Python.framework/Versions/3.8/lib/python3.8/unittest/case.py", line 227, in __exit__
    self._raiseFailure("{} not raised".format(exc_name))
  File "/usr/local/Cellar/python@3.8/3.8.12_1/Frameworks/Python.framework/Versions/3.8/lib/python3.8/unittest/case.py", line 164, in _raiseFailure
    raise self.test_case.failureException(msg)
AssertionError: VaccineManagementException not raised
]]></failure>
	</testcase>
	<testcase classname="test_cancellation_tests.TestCancellation" name="test_parametrized_Json_Case_NV (test='Case_NV_50')" time="0.000" timestamp="0001-01-01T00:00:00">
		<failure type="AssertionError" message="VaccineManagementException not raised"><![CDATA[Traceback (most recent call last):
  File "/usr/local/Cellar/python@3.8/3.8.12_1/Frameworks/Python.framework/Versions/3.8/lib/python3.8/unittest/case.py", line 60, in testPartExecutor
    yield
  File "/usr/local/Cellar/python@3.8/3.8.12_1/Frameworks/Python.framework/Versions/3.8/lib/python3.8/unittest/case.py", line 582, in subTest
    yield
  File "/Users/aaron/PycharmProjects/G89.2022.T21.FP/src/unittest/python/test_cancellation_tests.py", line 219, in test_parametrized_Json_Case_NV
    date_signature = my_manager.cancel_appointment(cancellation_json)
  File "/usr/local/Cellar/python@3.8/3.8.12_1/Frameworks/Python.framework/Versions/3.8/lib/python3.8/unittest/case.py", line 227, in __exit__
    self._raiseFailure("{} not raised".format(exc_name))
  File "/usr/local/Cellar/python@3.8/3.8.12_1/Frameworks/Python.framework/Versions/3.8/lib/python3.8/unittest/case.py", line 164, in _raiseFailure
    raise self.test_case.failureException(msg)
AssertionError: VaccineManagementException not raised
]]></failure>
	</testcase>
	<testcase classname="test_cancellation_tests.TestCancellation" name="test_parametrized_Json_Case_NV (test='Case_NV_51')" time="0.000" timestamp="0001-01-01T00:00:00">
		<failure type="AssertionError" message="VaccineManagementException not raised"><![CDATA[Traceback (most recent call last):
  File "/usr/local/Cellar/python@3.8/3.8.12_1/Frameworks/Python.framework/Versions/3.8/lib/python3.8/unittest/case.py", line 60, in testPartExecutor
    yield
  File "/usr/local/Cellar/python@3.8/3.8.12_1/Frameworks/Python.framework/Versions/3.8/lib/python3.8/unittest/case.py", line 582, in subTest
    yield
  File "/Users/aaron/PycharmProjects/G89.2022.T21.FP/src/unittest/python/test_cancellation_tests.py", line 219, in test_parametrized_Json_Case_NV
    date_signature = my_manager.cancel_appointment(cancellation_json)
  File "/usr/local/Cellar/python@3.8/3.8.12_1/Frameworks/Python.framework/Versions/3.8/lib/python3.8/unittest/case.py", line 227, in __exit__
    self._raiseFailure("{} not raised".format(exc_name))
  File "/usr/local/Cellar/python@3.8/3.8.12_1/Frameworks/Python.framework/Versions/3.8/lib/python3.8/unittest/case.py", line 164, in _raiseFailure
    raise self.test_case.failureException(msg)
AssertionError: VaccineManagementException not raised
]]></failure>
	</testcase>
	<testcase classname="test_cancellation_tests.TestCancellation" name="test_parametrized_Json_Case_NV (test='Case_NV_52')" time="0.000" timestamp="0001-01-01T00:00:00">
		<failure type="AssertionError" message="VaccineManagementException not raised"><![CDATA[Traceback (most recent call last):
  File "/usr/local/Cellar/python@3.8/3.8.12_1/Frameworks/Python.framework/Versions/3.8/lib/python3.8/unittest/case.py", line 60, in testPartExecutor
    yield
  File "/usr/local/Cellar/python@3.8/3.8.12_1/Frameworks/Python.framework/Versions/3.8/lib/python3.8/unittest/case.py", line 582, in subTest
    yield
  File "/Users/aaron/PycharmProjects/G89.2022.T21.FP/src/unittest/python/test_cancellation_tests.py", line 219, in test_parametrized_Json_Case_NV
    date_signature = my_manager.cancel_appointment(cancellation_json)
  File "/usr/local/Cellar/python@3.8/3.8.12_1/Frameworks/Python.framework/Versions/3.8/lib/python3.8/unittest/case.py", line 227, in __exit__
    self._raiseFailure("{} not raised".format(exc_name))
  File "/usr/local/Cellar/python@3.8/3.8.12_1/Frameworks/Python.framework/Versions/3.8/lib/python3.8/unittest/case.py", line 164, in _raiseFailure
    raise self.test_case.failureException(msg)
AssertionError: VaccineManagementException not raised
]]></failure>
	</testcase>
	<testcase classname="test_cancellation_tests.TestCancellation" name="test_parametrized_Json_Case_NV (test='Case_NV_53')" time="0.000" timestamp="0001-01-01T00:00:00">
		<failure type="AssertionError" message="VaccineManagementException not raised"><![CDATA[Traceback (most recent call last):
  File "/usr/local/Cellar/python@3.8/3.8.12_1/Frameworks/Python.framework/Versions/3.8/lib/python3.8/unittest/case.py", line 60, in testPartExecutor
    yield
  File "/usr/local/Cellar/python@3.8/3.8.12_1/Frameworks/Python.framework/Versions/3.8/lib/python3.8/unittest/case.py", line 582, in subTest
    yield
  File "/Users/aaron/PycharmProjects/G89.2022.T21.FP/src/unittest/python/test_cancellation_tests.py", line 219, in test_parametrized_Json_Case_NV
    date_signature = my_manager.cancel_appointment(cancellation_json)
  File "/usr/local/Cellar/python@3.8/3.8.12_1/Frameworks/Python.framework/Versions/3.8/lib/python3.8/unittest/case.py", line 227, in __exit__
    self._raiseFailure("{} not raised".format(exc_name))
  File "/usr/local/Cellar/python@3.8/3.8.12_1/Frameworks/Python.framework/Versions/3.8/lib/python3.8/unittest/case.py", line 164, in _raiseFailure
    raise self.test_case.failureException(msg)
AssertionError: VaccineManagementException not raised
]]></failure>
	</testcase>
	<testcase classname="test_cancellation_tests.TestCancellation" name="test_parametrized_Json_Case_NV (test='Case_NV_54')" time="0.000" timestamp="0001-01-01T00:00:00">
		<failure type="AssertionError" message="VaccineManagementException not raised"><![CDATA[Traceback (most recent call last):
  File "/usr/local/Cellar/python@3.8/3.8.12_1/Frameworks/Python.framework/Versions/3.8/lib/python3.8/unittest/case.py", line 60, in testPartExecutor
    yield
  File "/usr/local/Cellar/python@3.8/3.8.12_1/Frameworks/Python.framework/Versions/3.8/lib/python3.8/unittest/case.py", line 582, in subTest
    yield
  File "/Users/aaron/PycharmProjects/G89.2022.T21.FP/src/unittest/python/test_cancellation_tests.py", line 219, in test_parametrized_Json_Case_NV
    date_signature = my_manager.cancel_appointment(cancellation_json)
  File "/usr/local/Cellar/python@3.8/3.8.12_1/Frameworks/Python.framework/Versions/3.8/lib/python3.8/unittest/case.py", line 227, in __exit__
    self._raiseFailure("{} not raised".format(exc_name))
  File "/usr/local/Cellar/python@3.8/3.8.12_1/Frameworks/Python.framework/Versions/3.8/lib/python3.8/unittest/case.py", line 164, in _raiseFailure
    raise self.test_case.failureException(msg)
AssertionError: VaccineManagementException not raised
]]></failure>
	</testcase>
	<testcase classname="test_cancellation_tests.TestCancellation" name="test_parametrized_Json_Case_NV (test='Case_NV_55')" time="0.000" timestamp="0001-01-01T00:00:00">
		<failure type="AssertionError" message="VaccineManagementException not raised"><![CDATA[Traceback (most recent call last):
  File "/usr/local/Cellar/python@3.8/3.8.12_1/Frameworks/Python.framework/Versions/3.8/lib/python3.8/unittest/case.py", line 60, in testPartExecutor
    yield
  File "/usr/local/Cellar/python@3.8/3.8.12_1/Frameworks/Python.framework/Versions/3.8/lib/python3.8/unittest/case.py", line 582, in subTest
    yield
  File "/Users/aaron/PycharmProjects/G89.2022.T21.FP/src/unittest/python/test_cancellation_tests.py", line 219, in test_parametrized_Json_Case_NV
    date_signature = my_manager.cancel_appointment(cancellation_json)
  File "/usr/local/Cellar/python@3.8/3.8.12_1/Frameworks/Python.framework/Versions/3.8/lib/python3.8/unittest/case.py", line 227, in __exit__
    self._raiseFailure("{} not raised".format(exc_name))
  File "/usr/local/Cellar/python@3.8/3.8.12_1/Frameworks/Python.framework/Versions/3.8/lib/python3.8/unittest/case.py", line 164, in _raiseFailure
    raise self.test_case.failureException(msg)
AssertionError: VaccineManagementException not raised
]]></failure>
	</testcase>
	<testcase classname="test_cancellation_tests.TestCancellation" name="test_parametrized_Json_Case_NV (test='Case_NV_56')" time="0.238" timestamp="2022-05-20T23:21:34">
		<failure type="AssertionError" message="VaccineManagementException not raised"><![CDATA[Traceback (most recent call last):
  File "/usr/local/Cellar/python@3.8/3.8.12_1/Frameworks/Python.framework/Versions/3.8/lib/python3.8/unittest/case.py", line 60, in testPartExecutor
    yield
  File "/usr/local/Cellar/python@3.8/3.8.12_1/Frameworks/Python.framework/Versions/3.8/lib/python3.8/unittest/case.py", line 582, in subTest
    yield
  File "/Users/aaron/PycharmProjects/G89.2022.T21.FP/src/unittest/python/test_cancellation_tests.py", line 219, in test_parametrized_Json_Case_NV
    date_signature = my_manager.cancel_appointment(cancellation_json)
  File "/usr/local/Cellar/python@3.8/3.8.12_1/Frameworks/Python.framework/Versions/3.8/lib/python3.8/unittest/case.py", line 227, in __exit__
    self._raiseFailure("{} not raised".format(exc_name))
  File "/usr/local/Cellar/python@3.8/3.8.12_1/Frameworks/Python.framework/Versions/3.8/lib/python3.8/unittest/case.py", line 164, in _raiseFailure
    raise self.test_case.failureException(msg)
AssertionError: VaccineManagementException not raised
]]></failure>
	</testcase>
</testsuite>
