<?xml version="1.0" encoding="UTF-8"?>
<testsuite name="test_json_tests.TestJsons-20220520183918" tests="56" file="test_json_tests.py" time="0.227" timestamp="2022-05-20T18:39:19" failures="0" errors="56" skipped="0">
	<testcase classname="test_json_tests.TestJsons" name="test_Case_NV (test='Case_NV_02')" time="0.000" timestamp="0001-01-01T00:00:00">
		<error type="AttributeError" message="'__VaccineManager' object has no attribute 'cancel_appointment'"><![CDATA[Traceback (most recent call last):
  File "/usr/local/Cellar/python@3.8/3.8.12_1/Frameworks/Python.framework/Versions/3.8/lib/python3.8/unittest/case.py", line 60, in testPartExecutor
    yield
  File "/usr/local/Cellar/python@3.8/3.8.12_1/Frameworks/Python.framework/Versions/3.8/lib/python3.8/unittest/case.py", line 582, in subTest
    yield
  File "/Users/aaron/PycharmProjects/G89.2022.T21.FP/src/unittest/python/test_json_tests.py", line 210, in test_Case_NV
    date_signature = my_manager.cancel_appointment(cancellation_json)
AttributeError: '__VaccineManager' object has no attribute 'cancel_appointment'
]]></error>
	</testcase>
	<testcase classname="test_json_tests.TestJsons" name="test_Case_NV (test='Case_NV_03')" time="0.000" timestamp="0001-01-01T00:00:00">
		<error type="AttributeError" message="'__VaccineManager' object has no attribute 'cancel_appointment'"><![CDATA[Traceback (most recent call last):
  File "/usr/local/Cellar/python@3.8/3.8.12_1/Frameworks/Python.framework/Versions/3.8/lib/python3.8/unittest/case.py", line 60, in testPartExecutor
    yield
  File "/usr/local/Cellar/python@3.8/3.8.12_1/Frameworks/Python.framework/Versions/3.8/lib/python3.8/unittest/case.py", line 582, in subTest
    yield
  File "/Users/aaron/PycharmProjects/G89.2022.T21.FP/src/unittest/python/test_json_tests.py", line 210, in test_Case_NV
    date_signature = my_manager.cancel_appointment(cancellation_json)
AttributeError: '__VaccineManager' object has no attribute 'cancel_appointment'
]]></error>
	</testcase>
	<testcase classname="test_json_tests.TestJsons" name="test_Case_NV (test='Case_NV_04')" time="0.000" timestamp="0001-01-01T00:00:00">
		<error type="AttributeError" message="'__VaccineManager' object has no attribute 'cancel_appointment'"><![CDATA[Traceback (most recent call last):
  File "/usr/local/Cellar/python@3.8/3.8.12_1/Frameworks/Python.framework/Versions/3.8/lib/python3.8/unittest/case.py", line 60, in testPartExecutor
    yield
  File "/usr/local/Cellar/python@3.8/3.8.12_1/Frameworks/Python.framework/Versions/3.8/lib/python3.8/unittest/case.py", line 582, in subTest
    yield
  File "/Users/aaron/PycharmProjects/G89.2022.T21.FP/src/unittest/python/test_json_tests.py", line 210, in test_Case_NV
    date_signature = my_manager.cancel_appointment(cancellation_json)
AttributeError: '__VaccineManager' object has no attribute 'cancel_appointment'
]]></error>
	</testcase>
	<testcase classname="test_json_tests.TestJsons" name="test_Case_NV (test='Case_NV_05')" time="0.000" timestamp="0001-01-01T00:00:00">
		<error type="AttributeError" message="'__VaccineManager' object has no attribute 'cancel_appointment'"><![CDATA[Traceback (most recent call last):
  File "/usr/local/Cellar/python@3.8/3.8.12_1/Frameworks/Python.framework/Versions/3.8/lib/python3.8/unittest/case.py", line 60, in testPartExecutor
    yield
  File "/usr/local/Cellar/python@3.8/3.8.12_1/Frameworks/Python.framework/Versions/3.8/lib/python3.8/unittest/case.py", line 582, in subTest
    yield
  File "/Users/aaron/PycharmProjects/G89.2022.T21.FP/src/unittest/python/test_json_tests.py", line 210, in test_Case_NV
    date_signature = my_manager.cancel_appointment(cancellation_json)
AttributeError: '__VaccineManager' object has no attribute 'cancel_appointment'
]]></error>
	</testcase>
	<testcase classname="test_json_tests.TestJsons" name="test_Case_NV (test='Case_NV_06')" time="0.000" timestamp="0001-01-01T00:00:00">
		<error type="AttributeError" message="'__VaccineManager' object has no attribute 'cancel_appointment'"><![CDATA[Traceback (most recent call last):
  File "/usr/local/Cellar/python@3.8/3.8.12_1/Frameworks/Python.framework/Versions/3.8/lib/python3.8/unittest/case.py", line 60, in testPartExecutor
    yield
  File "/usr/local/Cellar/python@3.8/3.8.12_1/Frameworks/Python.framework/Versions/3.8/lib/python3.8/unittest/case.py", line 582, in subTest
    yield
  File "/Users/aaron/PycharmProjects/G89.2022.T21.FP/src/unittest/python/test_json_tests.py", line 210, in test_Case_NV
    date_signature = my_manager.cancel_appointment(cancellation_json)
AttributeError: '__VaccineManager' object has no attribute 'cancel_appointment'
]]></error>
	</testcase>
	<testcase classname="test_json_tests.TestJsons" name="test_Case_NV (test='Case_NV_07')" time="0.000" timestamp="0001-01-01T00:00:00">
		<error type="AttributeError" message="'__VaccineManager' object has no attribute 'cancel_appointment'"><![CDATA[Traceback (most recent call last):
  File "/usr/local/Cellar/python@3.8/3.8.12_1/Frameworks/Python.framework/Versions/3.8/lib/python3.8/unittest/case.py", line 60, in testPartExecutor
    yield
  File "/usr/local/Cellar/python@3.8/3.8.12_1/Frameworks/Python.framework/Versions/3.8/lib/python3.8/unittest/case.py", line 582, in subTest
    yield
  File "/Users/aaron/PycharmProjects/G89.2022.T21.FP/src/unittest/python/test_json_tests.py", line 210, in test_Case_NV
    date_signature = my_manager.cancel_appointment(cancellation_json)
AttributeError: '__VaccineManager' object has no attribute 'cancel_appointment'
]]></error>
	</testcase>
	<testcase classname="test_json_tests.TestJsons" name="test_Case_NV (test='Case_NV_08')" time="0.000" timestamp="0001-01-01T00:00:00">
		<error type="AttributeError" message="'__VaccineManager' object has no attribute 'cancel_appointment'"><![CDATA[Traceback (most recent call last):
  File "/usr/local/Cellar/python@3.8/3.8.12_1/Frameworks/Python.framework/Versions/3.8/lib/python3.8/unittest/case.py", line 60, in testPartExecutor
    yield
  File "/usr/local/Cellar/python@3.8/3.8.12_1/Frameworks/Python.framework/Versions/3.8/lib/python3.8/unittest/case.py", line 582, in subTest
    yield
  File "/Users/aaron/PycharmProjects/G89.2022.T21.FP/src/unittest/python/test_json_tests.py", line 210, in test_Case_NV
    date_signature = my_manager.cancel_appointment(cancellation_json)
AttributeError: '__VaccineManager' object has no attribute 'cancel_appointment'
]]></error>
	</testcase>
	<testcase classname="test_json_tests.TestJsons" name="test_Case_NV (test='Case_NV_09')" time="0.000" timestamp="0001-01-01T00:00:00">
		<error type="AttributeError" message="'__VaccineManager' object has no attribute 'cancel_appointment'"><![CDATA[Traceback (most recent call last):
  File "/usr/local/Cellar/python@3.8/3.8.12_1/Frameworks/Python.framework/Versions/3.8/lib/python3.8/unittest/case.py", line 60, in testPartExecutor
    yield
  File "/usr/local/Cellar/python@3.8/3.8.12_1/Frameworks/Python.framework/Versions/3.8/lib/python3.8/unittest/case.py", line 582, in subTest
    yield
  File "/Users/aaron/PycharmProjects/G89.2022.T21.FP/src/unittest/python/test_json_tests.py", line 210, in test_Case_NV
    date_signature = my_manager.cancel_appointment(cancellation_json)
AttributeError: '__VaccineManager' object has no attribute 'cancel_appointment'
]]></error>
	</testcase>
	<testcase classname="test_json_tests.TestJsons" name="test_Case_NV (test='Case_NV_10')" time="0.000" timestamp="0001-01-01T00:00:00">
		<error type="AttributeError" message="'__VaccineManager' object has no attribute 'cancel_appointment'"><![CDATA[Traceback (most recent call last):
  File "/usr/local/Cellar/python@3.8/3.8.12_1/Frameworks/Python.framework/Versions/3.8/lib/python3.8/unittest/case.py", line 60, in testPartExecutor
    yield
  File "/usr/local/Cellar/python@3.8/3.8.12_1/Frameworks/Python.framework/Versions/3.8/lib/python3.8/unittest/case.py", line 582, in subTest
    yield
  File "/Users/aaron/PycharmProjects/G89.2022.T21.FP/src/unittest/python/test_json_tests.py", line 210, in test_Case_NV
    date_signature = my_manager.cancel_appointment(cancellation_json)
AttributeError: '__VaccineManager' object has no attribute 'cancel_appointment'
]]></error>
	</testcase>
	<testcase classname="test_json_tests.TestJsons" name="test_Case_NV (test='Case_NV_11')" time="0.000" timestamp="0001-01-01T00:00:00">
		<error type="AttributeError" message="'__VaccineManager' object has no attribute 'cancel_appointment'"><![CDATA[Traceback (most recent call last):
  File "/usr/local/Cellar/python@3.8/3.8.12_1/Frameworks/Python.framework/Versions/3.8/lib/python3.8/unittest/case.py", line 60, in testPartExecutor
    yield
  File "/usr/local/Cellar/python@3.8/3.8.12_1/Frameworks/Python.framework/Versions/3.8/lib/python3.8/unittest/case.py", line 582, in subTest
    yield
  File "/Users/aaron/PycharmProjects/G89.2022.T21.FP/src/unittest/python/test_json_tests.py", line 210, in test_Case_NV
    date_signature = my_manager.cancel_appointment(cancellation_json)
AttributeError: '__VaccineManager' object has no attribute 'cancel_appointment'
]]></error>
	</testcase>
	<testcase classname="test_json_tests.TestJsons" name="test_Case_NV (test='Case_NV_12')" time="0.000" timestamp="0001-01-01T00:00:00">
		<error type="AttributeError" message="'__VaccineManager' object has no attribute 'cancel_appointment'"><![CDATA[Traceback (most recent call last):
  File "/usr/local/Cellar/python@3.8/3.8.12_1/Frameworks/Python.framework/Versions/3.8/lib/python3.8/unittest/case.py", line 60, in testPartExecutor
    yield
  File "/usr/local/Cellar/python@3.8/3.8.12_1/Frameworks/Python.framework/Versions/3.8/lib/python3.8/unittest/case.py", line 582, in subTest
    yield
  File "/Users/aaron/PycharmProjects/G89.2022.T21.FP/src/unittest/python/test_json_tests.py", line 210, in test_Case_NV
    date_signature = my_manager.cancel_appointment(cancellation_json)
AttributeError: '__VaccineManager' object has no attribute 'cancel_appointment'
]]></error>
	</testcase>
	<testcase classname="test_json_tests.TestJsons" name="test_Case_NV (test='Case_NV_13')" time="0.000" timestamp="0001-01-01T00:00:00">
		<error type="AttributeError" message="'__VaccineManager' object has no attribute 'cancel_appointment'"><![CDATA[Traceback (most recent call last):
  File "/usr/local/Cellar/python@3.8/3.8.12_1/Frameworks/Python.framework/Versions/3.8/lib/python3.8/unittest/case.py", line 60, in testPartExecutor
    yield
  File "/usr/local/Cellar/python@3.8/3.8.12_1/Frameworks/Python.framework/Versions/3.8/lib/python3.8/unittest/case.py", line 582, in subTest
    yield
  File "/Users/aaron/PycharmProjects/G89.2022.T21.FP/src/unittest/python/test_json_tests.py", line 210, in test_Case_NV
    date_signature = my_manager.cancel_appointment(cancellation_json)
AttributeError: '__VaccineManager' object has no attribute 'cancel_appointment'
]]></error>
	</testcase>
	<testcase classname="test_json_tests.TestJsons" name="test_Case_NV (test='Case_NV_14')" time="0.000" timestamp="0001-01-01T00:00:00">
		<error type="AttributeError" message="'__VaccineManager' object has no attribute 'cancel_appointment'"><![CDATA[Traceback (most recent call last):
  File "/usr/local/Cellar/python@3.8/3.8.12_1/Frameworks/Python.framework/Versions/3.8/lib/python3.8/unittest/case.py", line 60, in testPartExecutor
    yield
  File "/usr/local/Cellar/python@3.8/3.8.12_1/Frameworks/Python.framework/Versions/3.8/lib/python3.8/unittest/case.py", line 582, in subTest
    yield
  File "/Users/aaron/PycharmProjects/G89.2022.T21.FP/src/unittest/python/test_json_tests.py", line 210, in test_Case_NV
    date_signature = my_manager.cancel_appointment(cancellation_json)
AttributeError: '__VaccineManager' object has no attribute 'cancel_appointment'
]]></error>
	</testcase>
	<testcase classname="test_json_tests.TestJsons" name="test_Case_NV (test='Case_NV_15')" time="0.000" timestamp="0001-01-01T00:00:00">
		<error type="AttributeError" message="'__VaccineManager' object has no attribute 'cancel_appointment'"><![CDATA[Traceback (most recent call last):
  File "/usr/local/Cellar/python@3.8/3.8.12_1/Frameworks/Python.framework/Versions/3.8/lib/python3.8/unittest/case.py", line 60, in testPartExecutor
    yield
  File "/usr/local/Cellar/python@3.8/3.8.12_1/Frameworks/Python.framework/Versions/3.8/lib/python3.8/unittest/case.py", line 582, in subTest
    yield
  File "/Users/aaron/PycharmProjects/G89.2022.T21.FP/src/unittest/python/test_json_tests.py", line 210, in test_Case_NV
    date_signature = my_manager.cancel_appointment(cancellation_json)
AttributeError: '__VaccineManager' object has no attribute 'cancel_appointment'
]]></error>
	</testcase>
	<testcase classname="test_json_tests.TestJsons" name="test_Case_NV (test='Case_NV_16')" time="0.000" timestamp="0001-01-01T00:00:00">
		<error type="AttributeError" message="'__VaccineManager' object has no attribute 'cancel_appointment'"><![CDATA[Traceback (most recent call last):
  File "/usr/local/Cellar/python@3.8/3.8.12_1/Frameworks/Python.framework/Versions/3.8/lib/python3.8/unittest/case.py", line 60, in testPartExecutor
    yield
  File "/usr/local/Cellar/python@3.8/3.8.12_1/Frameworks/Python.framework/Versions/3.8/lib/python3.8/unittest/case.py", line 582, in subTest
    yield
  File "/Users/aaron/PycharmProjects/G89.2022.T21.FP/src/unittest/python/test_json_tests.py", line 210, in test_Case_NV
    date_signature = my_manager.cancel_appointment(cancellation_json)
AttributeError: '__VaccineManager' object has no attribute 'cancel_appointment'
]]></error>
	</testcase>
	<testcase classname="test_json_tests.TestJsons" name="test_Case_NV (test='Case_NV_17')" time="0.000" timestamp="0001-01-01T00:00:00">
		<error type="AttributeError" message="'__VaccineManager' object has no attribute 'cancel_appointment'"><![CDATA[Traceback (most recent call last):
  File "/usr/local/Cellar/python@3.8/3.8.12_1/Frameworks/Python.framework/Versions/3.8/lib/python3.8/unittest/case.py", line 60, in testPartExecutor
    yield
  File "/usr/local/Cellar/python@3.8/3.8.12_1/Frameworks/Python.framework/Versions/3.8/lib/python3.8/unittest/case.py", line 582, in subTest
    yield
  File "/Users/aaron/PycharmProjects/G89.2022.T21.FP/src/unittest/python/test_json_tests.py", line 210, in test_Case_NV
    date_signature = my_manager.cancel_appointment(cancellation_json)
AttributeError: '__VaccineManager' object has no attribute 'cancel_appointment'
]]></error>
	</testcase>
	<testcase classname="test_json_tests.TestJsons" name="test_Case_NV (test='Case_NV_18')" time="0.000" timestamp="0001-01-01T00:00:00">
		<error type="AttributeError" message="'__VaccineManager' object has no attribute 'cancel_appointment'"><![CDATA[Traceback (most recent call last):
  File "/usr/local/Cellar/python@3.8/3.8.12_1/Frameworks/Python.framework/Versions/3.8/lib/python3.8/unittest/case.py", line 60, in testPartExecutor
    yield
  File "/usr/local/Cellar/python@3.8/3.8.12_1/Frameworks/Python.framework/Versions/3.8/lib/python3.8/unittest/case.py", line 582, in subTest
    yield
  File "/Users/aaron/PycharmProjects/G89.2022.T21.FP/src/unittest/python/test_json_tests.py", line 210, in test_Case_NV
    date_signature = my_manager.cancel_appointment(cancellation_json)
AttributeError: '__VaccineManager' object has no attribute 'cancel_appointment'
]]></error>
	</testcase>
	<testcase classname="test_json_tests.TestJsons" name="test_Case_NV (test='Case_NV_19')" time="0.000" timestamp="0001-01-01T00:00:00">
		<error type="AttributeError" message="'__VaccineManager' object has no attribute 'cancel_appointment'"><![CDATA[Traceback (most recent call last):
  File "/usr/local/Cellar/python@3.8/3.8.12_1/Frameworks/Python.framework/Versions/3.8/lib/python3.8/unittest/case.py", line 60, in testPartExecutor
    yield
  File "/usr/local/Cellar/python@3.8/3.8.12_1/Frameworks/Python.framework/Versions/3.8/lib/python3.8/unittest/case.py", line 582, in subTest
    yield
  File "/Users/aaron/PycharmProjects/G89.2022.T21.FP/src/unittest/python/test_json_tests.py", line 210, in test_Case_NV
    date_signature = my_manager.cancel_appointment(cancellation_json)
AttributeError: '__VaccineManager' object has no attribute 'cancel_appointment'
]]></error>
	</testcase>
	<testcase classname="test_json_tests.TestJsons" name="test_Case_NV (test='Case_NV_20')" time="0.000" timestamp="0001-01-01T00:00:00">
		<error type="AttributeError" message="'__VaccineManager' object has no attribute 'cancel_appointment'"><![CDATA[Traceback (most recent call last):
  File "/usr/local/Cellar/python@3.8/3.8.12_1/Frameworks/Python.framework/Versions/3.8/lib/python3.8/unittest/case.py", line 60, in testPartExecutor
    yield
  File "/usr/local/Cellar/python@3.8/3.8.12_1/Frameworks/Python.framework/Versions/3.8/lib/python3.8/unittest/case.py", line 582, in subTest
    yield
  File "/Users/aaron/PycharmProjects/G89.2022.T21.FP/src/unittest/python/test_json_tests.py", line 210, in test_Case_NV
    date_signature = my_manager.cancel_appointment(cancellation_json)
AttributeError: '__VaccineManager' object has no attribute 'cancel_appointment'
]]></error>
	</testcase>
	<testcase classname="test_json_tests.TestJsons" name="test_Case_NV (test='Case_NV_21')" time="0.000" timestamp="0001-01-01T00:00:00">
		<error type="AttributeError" message="'__VaccineManager' object has no attribute 'cancel_appointment'"><![CDATA[Traceback (most recent call last):
  File "/usr/local/Cellar/python@3.8/3.8.12_1/Frameworks/Python.framework/Versions/3.8/lib/python3.8/unittest/case.py", line 60, in testPartExecutor
    yield
  File "/usr/local/Cellar/python@3.8/3.8.12_1/Frameworks/Python.framework/Versions/3.8/lib/python3.8/unittest/case.py", line 582, in subTest
    yield
  File "/Users/aaron/PycharmProjects/G89.2022.T21.FP/src/unittest/python/test_json_tests.py", line 210, in test_Case_NV
    date_signature = my_manager.cancel_appointment(cancellation_json)
AttributeError: '__VaccineManager' object has no attribute 'cancel_appointment'
]]></error>
	</testcase>
	<testcase classname="test_json_tests.TestJsons" name="test_Case_NV (test='Case_NV_22')" time="0.000" timestamp="0001-01-01T00:00:00">
		<error type="AttributeError" message="'__VaccineManager' object has no attribute 'cancel_appointment'"><![CDATA[Traceback (most recent call last):
  File "/usr/local/Cellar/python@3.8/3.8.12_1/Frameworks/Python.framework/Versions/3.8/lib/python3.8/unittest/case.py", line 60, in testPartExecutor
    yield
  File "/usr/local/Cellar/python@3.8/3.8.12_1/Frameworks/Python.framework/Versions/3.8/lib/python3.8/unittest/case.py", line 582, in subTest
    yield
  File "/Users/aaron/PycharmProjects/G89.2022.T21.FP/src/unittest/python/test_json_tests.py", line 210, in test_Case_NV
    date_signature = my_manager.cancel_appointment(cancellation_json)
AttributeError: '__VaccineManager' object has no attribute 'cancel_appointment'
]]></error>
	</testcase>
	<testcase classname="test_json_tests.TestJsons" name="test_Case_NV (test='Case_NV_23')" time="0.000" timestamp="0001-01-01T00:00:00">
		<error type="AttributeError" message="'__VaccineManager' object has no attribute 'cancel_appointment'"><![CDATA[Traceback (most recent call last):
  File "/usr/local/Cellar/python@3.8/3.8.12_1/Frameworks/Python.framework/Versions/3.8/lib/python3.8/unittest/case.py", line 60, in testPartExecutor
    yield
  File "/usr/local/Cellar/python@3.8/3.8.12_1/Frameworks/Python.framework/Versions/3.8/lib/python3.8/unittest/case.py", line 582, in subTest
    yield
  File "/Users/aaron/PycharmProjects/G89.2022.T21.FP/src/unittest/python/test_json_tests.py", line 210, in test_Case_NV
    date_signature = my_manager.cancel_appointment(cancellation_json)
AttributeError: '__VaccineManager' object has no attribute 'cancel_appointment'
]]></error>
	</testcase>
	<testcase classname="test_json_tests.TestJsons" name="test_Case_NV (test='Case_NV_24')" time="0.000" timestamp="0001-01-01T00:00:00">
		<error type="AttributeError" message="'__VaccineManager' object has no attribute 'cancel_appointment'"><![CDATA[Traceback (most recent call last):
  File "/usr/local/Cellar/python@3.8/3.8.12_1/Frameworks/Python.framework/Versions/3.8/lib/python3.8/unittest/case.py", line 60, in testPartExecutor
    yield
  File "/usr/local/Cellar/python@3.8/3.8.12_1/Frameworks/Python.framework/Versions/3.8/lib/python3.8/unittest/case.py", line 582, in subTest
    yield
  File "/Users/aaron/PycharmProjects/G89.2022.T21.FP/src/unittest/python/test_json_tests.py", line 210, in test_Case_NV
    date_signature = my_manager.cancel_appointment(cancellation_json)
AttributeError: '__VaccineManager' object has no attribute 'cancel_appointment'
]]></error>
	</testcase>
	<testcase classname="test_json_tests.TestJsons" name="test_Case_NV (test='Case_NV_25')" time="0.000" timestamp="0001-01-01T00:00:00">
		<error type="AttributeError" message="'__VaccineManager' object has no attribute 'cancel_appointment'"><![CDATA[Traceback (most recent call last):
  File "/usr/local/Cellar/python@3.8/3.8.12_1/Frameworks/Python.framework/Versions/3.8/lib/python3.8/unittest/case.py", line 60, in testPartExecutor
    yield
  File "/usr/local/Cellar/python@3.8/3.8.12_1/Frameworks/Python.framework/Versions/3.8/lib/python3.8/unittest/case.py", line 582, in subTest
    yield
  File "/Users/aaron/PycharmProjects/G89.2022.T21.FP/src/unittest/python/test_json_tests.py", line 210, in test_Case_NV
    date_signature = my_manager.cancel_appointment(cancellation_json)
AttributeError: '__VaccineManager' object has no attribute 'cancel_appointment'
]]></error>
	</testcase>
	<testcase classname="test_json_tests.TestJsons" name="test_Case_NV (test='Case_NV_26')" time="0.000" timestamp="0001-01-01T00:00:00">
		<error type="AttributeError" message="'__VaccineManager' object has no attribute 'cancel_appointment'"><![CDATA[Traceback (most recent call last):
  File "/usr/local/Cellar/python@3.8/3.8.12_1/Frameworks/Python.framework/Versions/3.8/lib/python3.8/unittest/case.py", line 60, in testPartExecutor
    yield
  File "/usr/local/Cellar/python@3.8/3.8.12_1/Frameworks/Python.framework/Versions/3.8/lib/python3.8/unittest/case.py", line 582, in subTest
    yield
  File "/Users/aaron/PycharmProjects/G89.2022.T21.FP/src/unittest/python/test_json_tests.py", line 210, in test_Case_NV
    date_signature = my_manager.cancel_appointment(cancellation_json)
AttributeError: '__VaccineManager' object has no attribute 'cancel_appointment'
]]></error>
	</testcase>
	<testcase classname="test_json_tests.TestJsons" name="test_Case_NV (test='Case_NV_27')" time="0.000" timestamp="0001-01-01T00:00:00">
		<error type="AttributeError" message="'__VaccineManager' object has no attribute 'cancel_appointment'"><![CDATA[Traceback (most recent call last):
  File "/usr/local/Cellar/python@3.8/3.8.12_1/Frameworks/Python.framework/Versions/3.8/lib/python3.8/unittest/case.py", line 60, in testPartExecutor
    yield
  File "/usr/local/Cellar/python@3.8/3.8.12_1/Frameworks/Python.framework/Versions/3.8/lib/python3.8/unittest/case.py", line 582, in subTest
    yield
  File "/Users/aaron/PycharmProjects/G89.2022.T21.FP/src/unittest/python/test_json_tests.py", line 210, in test_Case_NV
    date_signature = my_manager.cancel_appointment(cancellation_json)
AttributeError: '__VaccineManager' object has no attribute 'cancel_appointment'
]]></error>
	</testcase>
	<testcase classname="test_json_tests.TestJsons" name="test_Case_NV (test='Case_NV_28')" time="0.000" timestamp="0001-01-01T00:00:00">
		<error type="AttributeError" message="'__VaccineManager' object has no attribute 'cancel_appointment'"><![CDATA[Traceback (most recent call last):
  File "/usr/local/Cellar/python@3.8/3.8.12_1/Frameworks/Python.framework/Versions/3.8/lib/python3.8/unittest/case.py", line 60, in testPartExecutor
    yield
  File "/usr/local/Cellar/python@3.8/3.8.12_1/Frameworks/Python.framework/Versions/3.8/lib/python3.8/unittest/case.py", line 582, in subTest
    yield
  File "/Users/aaron/PycharmProjects/G89.2022.T21.FP/src/unittest/python/test_json_tests.py", line 210, in test_Case_NV
    date_signature = my_manager.cancel_appointment(cancellation_json)
AttributeError: '__VaccineManager' object has no attribute 'cancel_appointment'
]]></error>
	</testcase>
	<testcase classname="test_json_tests.TestJsons" name="test_Case_NV (test='Case_NV_29')" time="0.000" timestamp="0001-01-01T00:00:00">
		<error type="AttributeError" message="'__VaccineManager' object has no attribute 'cancel_appointment'"><![CDATA[Traceback (most recent call last):
  File "/usr/local/Cellar/python@3.8/3.8.12_1/Frameworks/Python.framework/Versions/3.8/lib/python3.8/unittest/case.py", line 60, in testPartExecutor
    yield
  File "/usr/local/Cellar/python@3.8/3.8.12_1/Frameworks/Python.framework/Versions/3.8/lib/python3.8/unittest/case.py", line 582, in subTest
    yield
  File "/Users/aaron/PycharmProjects/G89.2022.T21.FP/src/unittest/python/test_json_tests.py", line 210, in test_Case_NV
    date_signature = my_manager.cancel_appointment(cancellation_json)
AttributeError: '__VaccineManager' object has no attribute 'cancel_appointment'
]]></error>
	</testcase>
	<testcase classname="test_json_tests.TestJsons" name="test_Case_NV (test='Case_NV_30')" time="0.000" timestamp="0001-01-01T00:00:00">
		<error type="AttributeError" message="'__VaccineManager' object has no attribute 'cancel_appointment'"><![CDATA[Traceback (most recent call last):
  File "/usr/local/Cellar/python@3.8/3.8.12_1/Frameworks/Python.framework/Versions/3.8/lib/python3.8/unittest/case.py", line 60, in testPartExecutor
    yield
  File "/usr/local/Cellar/python@3.8/3.8.12_1/Frameworks/Python.framework/Versions/3.8/lib/python3.8/unittest/case.py", line 582, in subTest
    yield
  File "/Users/aaron/PycharmProjects/G89.2022.T21.FP/src/unittest/python/test_json_tests.py", line 210, in test_Case_NV
    date_signature = my_manager.cancel_appointment(cancellation_json)
AttributeError: '__VaccineManager' object has no attribute 'cancel_appointment'
]]></error>
	</testcase>
	<testcase classname="test_json_tests.TestJsons" name="test_Case_NV (test='Case_NV_31')" time="0.000" timestamp="0001-01-01T00:00:00">
		<error type="AttributeError" message="'__VaccineManager' object has no attribute 'cancel_appointment'"><![CDATA[Traceback (most recent call last):
  File "/usr/local/Cellar/python@3.8/3.8.12_1/Frameworks/Python.framework/Versions/3.8/lib/python3.8/unittest/case.py", line 60, in testPartExecutor
    yield
  File "/usr/local/Cellar/python@3.8/3.8.12_1/Frameworks/Python.framework/Versions/3.8/lib/python3.8/unittest/case.py", line 582, in subTest
    yield
  File "/Users/aaron/PycharmProjects/G89.2022.T21.FP/src/unittest/python/test_json_tests.py", line 210, in test_Case_NV
    date_signature = my_manager.cancel_appointment(cancellation_json)
AttributeError: '__VaccineManager' object has no attribute 'cancel_appointment'
]]></error>
	</testcase>
	<testcase classname="test_json_tests.TestJsons" name="test_Case_NV (test='Case_NV_32')" time="0.000" timestamp="0001-01-01T00:00:00">
		<error type="AttributeError" message="'__VaccineManager' object has no attribute 'cancel_appointment'"><![CDATA[Traceback (most recent call last):
  File "/usr/local/Cellar/python@3.8/3.8.12_1/Frameworks/Python.framework/Versions/3.8/lib/python3.8/unittest/case.py", line 60, in testPartExecutor
    yield
  File "/usr/local/Cellar/python@3.8/3.8.12_1/Frameworks/Python.framework/Versions/3.8/lib/python3.8/unittest/case.py", line 582, in subTest
    yield
  File "/Users/aaron/PycharmProjects/G89.2022.T21.FP/src/unittest/python/test_json_tests.py", line 210, in test_Case_NV
    date_signature = my_manager.cancel_appointment(cancellation_json)
AttributeError: '__VaccineManager' object has no attribute 'cancel_appointment'
]]></error>
	</testcase>
	<testcase classname="test_json_tests.TestJsons" name="test_Case_NV (test='Case_NV_33')" time="0.000" timestamp="0001-01-01T00:00:00">
		<error type="AttributeError" message="'__VaccineManager' object has no attribute 'cancel_appointment'"><![CDATA[Traceback (most recent call last):
  File "/usr/local/Cellar/python@3.8/3.8.12_1/Frameworks/Python.framework/Versions/3.8/lib/python3.8/unittest/case.py", line 60, in testPartExecutor
    yield
  File "/usr/local/Cellar/python@3.8/3.8.12_1/Frameworks/Python.framework/Versions/3.8/lib/python3.8/unittest/case.py", line 582, in subTest
    yield
  File "/Users/aaron/PycharmProjects/G89.2022.T21.FP/src/unittest/python/test_json_tests.py", line 210, in test_Case_NV
    date_signature = my_manager.cancel_appointment(cancellation_json)
AttributeError: '__VaccineManager' object has no attribute 'cancel_appointment'
]]></error>
	</testcase>
	<testcase classname="test_json_tests.TestJsons" name="test_Case_NV (test='Case_NV_34')" time="0.000" timestamp="0001-01-01T00:00:00">
		<error type="AttributeError" message="'__VaccineManager' object has no attribute 'cancel_appointment'"><![CDATA[Traceback (most recent call last):
  File "/usr/local/Cellar/python@3.8/3.8.12_1/Frameworks/Python.framework/Versions/3.8/lib/python3.8/unittest/case.py", line 60, in testPartExecutor
    yield
  File "/usr/local/Cellar/python@3.8/3.8.12_1/Frameworks/Python.framework/Versions/3.8/lib/python3.8/unittest/case.py", line 582, in subTest
    yield
  File "/Users/aaron/PycharmProjects/G89.2022.T21.FP/src/unittest/python/test_json_tests.py", line 210, in test_Case_NV
    date_signature = my_manager.cancel_appointment(cancellation_json)
AttributeError: '__VaccineManager' object has no attribute 'cancel_appointment'
]]></error>
	</testcase>
	<testcase classname="test_json_tests.TestJsons" name="test_Case_NV (test='Case_NV_35')" time="0.000" timestamp="0001-01-01T00:00:00">
		<error type="AttributeError" message="'__VaccineManager' object has no attribute 'cancel_appointment'"><![CDATA[Traceback (most recent call last):
  File "/usr/local/Cellar/python@3.8/3.8.12_1/Frameworks/Python.framework/Versions/3.8/lib/python3.8/unittest/case.py", line 60, in testPartExecutor
    yield
  File "/usr/local/Cellar/python@3.8/3.8.12_1/Frameworks/Python.framework/Versions/3.8/lib/python3.8/unittest/case.py", line 582, in subTest
    yield
  File "/Users/aaron/PycharmProjects/G89.2022.T21.FP/src/unittest/python/test_json_tests.py", line 210, in test_Case_NV
    date_signature = my_manager.cancel_appointment(cancellation_json)
AttributeError: '__VaccineManager' object has no attribute 'cancel_appointment'
]]></error>
	</testcase>
	<testcase classname="test_json_tests.TestJsons" name="test_Case_NV (test='Case_NV_36')" time="0.000" timestamp="0001-01-01T00:00:00">
		<error type="AttributeError" message="'__VaccineManager' object has no attribute 'cancel_appointment'"><![CDATA[Traceback (most recent call last):
  File "/usr/local/Cellar/python@3.8/3.8.12_1/Frameworks/Python.framework/Versions/3.8/lib/python3.8/unittest/case.py", line 60, in testPartExecutor
    yield
  File "/usr/local/Cellar/python@3.8/3.8.12_1/Frameworks/Python.framework/Versions/3.8/lib/python3.8/unittest/case.py", line 582, in subTest
    yield
  File "/Users/aaron/PycharmProjects/G89.2022.T21.FP/src/unittest/python/test_json_tests.py", line 210, in test_Case_NV
    date_signature = my_manager.cancel_appointment(cancellation_json)
AttributeError: '__VaccineManager' object has no attribute 'cancel_appointment'
]]></error>
	</testcase>
	<testcase classname="test_json_tests.TestJsons" name="test_Case_NV (test='Case_NV_37')" time="0.000" timestamp="0001-01-01T00:00:00">
		<error type="AttributeError" message="'__VaccineManager' object has no attribute 'cancel_appointment'"><![CDATA[Traceback (most recent call last):
  File "/usr/local/Cellar/python@3.8/3.8.12_1/Frameworks/Python.framework/Versions/3.8/lib/python3.8/unittest/case.py", line 60, in testPartExecutor
    yield
  File "/usr/local/Cellar/python@3.8/3.8.12_1/Frameworks/Python.framework/Versions/3.8/lib/python3.8/unittest/case.py", line 582, in subTest
    yield
  File "/Users/aaron/PycharmProjects/G89.2022.T21.FP/src/unittest/python/test_json_tests.py", line 210, in test_Case_NV
    date_signature = my_manager.cancel_appointment(cancellation_json)
AttributeError: '__VaccineManager' object has no attribute 'cancel_appointment'
]]></error>
	</testcase>
	<testcase classname="test_json_tests.TestJsons" name="test_Case_NV (test='Case_NV_38')" time="0.000" timestamp="0001-01-01T00:00:00">
		<error type="AttributeError" message="'__VaccineManager' object has no attribute 'cancel_appointment'"><![CDATA[Traceback (most recent call last):
  File "/usr/local/Cellar/python@3.8/3.8.12_1/Frameworks/Python.framework/Versions/3.8/lib/python3.8/unittest/case.py", line 60, in testPartExecutor
    yield
  File "/usr/local/Cellar/python@3.8/3.8.12_1/Frameworks/Python.framework/Versions/3.8/lib/python3.8/unittest/case.py", line 582, in subTest
    yield
  File "/Users/aaron/PycharmProjects/G89.2022.T21.FP/src/unittest/python/test_json_tests.py", line 210, in test_Case_NV
    date_signature = my_manager.cancel_appointment(cancellation_json)
AttributeError: '__VaccineManager' object has no attribute 'cancel_appointment'
]]></error>
	</testcase>
	<testcase classname="test_json_tests.TestJsons" name="test_Case_NV (test='Case_NV_39')" time="0.000" timestamp="0001-01-01T00:00:00">
		<error type="AttributeError" message="'__VaccineManager' object has no attribute 'cancel_appointment'"><![CDATA[Traceback (most recent call last):
  File "/usr/local/Cellar/python@3.8/3.8.12_1/Frameworks/Python.framework/Versions/3.8/lib/python3.8/unittest/case.py", line 60, in testPartExecutor
    yield
  File "/usr/local/Cellar/python@3.8/3.8.12_1/Frameworks/Python.framework/Versions/3.8/lib/python3.8/unittest/case.py", line 582, in subTest
    yield
  File "/Users/aaron/PycharmProjects/G89.2022.T21.FP/src/unittest/python/test_json_tests.py", line 210, in test_Case_NV
    date_signature = my_manager.cancel_appointment(cancellation_json)
AttributeError: '__VaccineManager' object has no attribute 'cancel_appointment'
]]></error>
	</testcase>
	<testcase classname="test_json_tests.TestJsons" name="test_Case_NV (test='Case_NV_40')" time="0.000" timestamp="0001-01-01T00:00:00">
		<error type="AttributeError" message="'__VaccineManager' object has no attribute 'cancel_appointment'"><![CDATA[Traceback (most recent call last):
  File "/usr/local/Cellar/python@3.8/3.8.12_1/Frameworks/Python.framework/Versions/3.8/lib/python3.8/unittest/case.py", line 60, in testPartExecutor
    yield
  File "/usr/local/Cellar/python@3.8/3.8.12_1/Frameworks/Python.framework/Versions/3.8/lib/python3.8/unittest/case.py", line 582, in subTest
    yield
  File "/Users/aaron/PycharmProjects/G89.2022.T21.FP/src/unittest/python/test_json_tests.py", line 210, in test_Case_NV
    date_signature = my_manager.cancel_appointment(cancellation_json)
AttributeError: '__VaccineManager' object has no attribute 'cancel_appointment'
]]></error>
	</testcase>
	<testcase classname="test_json_tests.TestJsons" name="test_Case_NV (test='Case_NV_41')" time="0.000" timestamp="0001-01-01T00:00:00">
		<error type="AttributeError" message="'__VaccineManager' object has no attribute 'cancel_appointment'"><![CDATA[Traceback (most recent call last):
  File "/usr/local/Cellar/python@3.8/3.8.12_1/Frameworks/Python.framework/Versions/3.8/lib/python3.8/unittest/case.py", line 60, in testPartExecutor
    yield
  File "/usr/local/Cellar/python@3.8/3.8.12_1/Frameworks/Python.framework/Versions/3.8/lib/python3.8/unittest/case.py", line 582, in subTest
    yield
  File "/Users/aaron/PycharmProjects/G89.2022.T21.FP/src/unittest/python/test_json_tests.py", line 210, in test_Case_NV
    date_signature = my_manager.cancel_appointment(cancellation_json)
AttributeError: '__VaccineManager' object has no attribute 'cancel_appointment'
]]></error>
	</testcase>
	<testcase classname="test_json_tests.TestJsons" name="test_Case_NV (test='Case_NV_42')" time="0.000" timestamp="0001-01-01T00:00:00">
		<error type="AttributeError" message="'__VaccineManager' object has no attribute 'cancel_appointment'"><![CDATA[Traceback (most recent call last):
  File "/usr/local/Cellar/python@3.8/3.8.12_1/Frameworks/Python.framework/Versions/3.8/lib/python3.8/unittest/case.py", line 60, in testPartExecutor
    yield
  File "/usr/local/Cellar/python@3.8/3.8.12_1/Frameworks/Python.framework/Versions/3.8/lib/python3.8/unittest/case.py", line 582, in subTest
    yield
  File "/Users/aaron/PycharmProjects/G89.2022.T21.FP/src/unittest/python/test_json_tests.py", line 210, in test_Case_NV
    date_signature = my_manager.cancel_appointment(cancellation_json)
AttributeError: '__VaccineManager' object has no attribute 'cancel_appointment'
]]></error>
	</testcase>
	<testcase classname="test_json_tests.TestJsons" name="test_Case_NV (test='Case_NV_43')" time="0.000" timestamp="0001-01-01T00:00:00">
		<error type="AttributeError" message="'__VaccineManager' object has no attribute 'cancel_appointment'"><![CDATA[Traceback (most recent call last):
  File "/usr/local/Cellar/python@3.8/3.8.12_1/Frameworks/Python.framework/Versions/3.8/lib/python3.8/unittest/case.py", line 60, in testPartExecutor
    yield
  File "/usr/local/Cellar/python@3.8/3.8.12_1/Frameworks/Python.framework/Versions/3.8/lib/python3.8/unittest/case.py", line 582, in subTest
    yield
  File "/Users/aaron/PycharmProjects/G89.2022.T21.FP/src/unittest/python/test_json_tests.py", line 210, in test_Case_NV
    date_signature = my_manager.cancel_appointment(cancellation_json)
AttributeError: '__VaccineManager' object has no attribute 'cancel_appointment'
]]></error>
	</testcase>
	<testcase classname="test_json_tests.TestJsons" name="test_Case_NV (test='Case_NV_44')" time="0.000" timestamp="0001-01-01T00:00:00">
		<error type="AttributeError" message="'__VaccineManager' object has no attribute 'cancel_appointment'"><![CDATA[Traceback (most recent call last):
  File "/usr/local/Cellar/python@3.8/3.8.12_1/Frameworks/Python.framework/Versions/3.8/lib/python3.8/unittest/case.py", line 60, in testPartExecutor
    yield
  File "/usr/local/Cellar/python@3.8/3.8.12_1/Frameworks/Python.framework/Versions/3.8/lib/python3.8/unittest/case.py", line 582, in subTest
    yield
  File "/Users/aaron/PycharmProjects/G89.2022.T21.FP/src/unittest/python/test_json_tests.py", line 210, in test_Case_NV
    date_signature = my_manager.cancel_appointment(cancellation_json)
AttributeError: '__VaccineManager' object has no attribute 'cancel_appointment'
]]></error>
	</testcase>
	<testcase classname="test_json_tests.TestJsons" name="test_Case_NV (test='Case_NV_45')" time="0.000" timestamp="0001-01-01T00:00:00">
		<error type="AttributeError" message="'__VaccineManager' object has no attribute 'cancel_appointment'"><![CDATA[Traceback (most recent call last):
  File "/usr/local/Cellar/python@3.8/3.8.12_1/Frameworks/Python.framework/Versions/3.8/lib/python3.8/unittest/case.py", line 60, in testPartExecutor
    yield
  File "/usr/local/Cellar/python@3.8/3.8.12_1/Frameworks/Python.framework/Versions/3.8/lib/python3.8/unittest/case.py", line 582, in subTest
    yield
  File "/Users/aaron/PycharmProjects/G89.2022.T21.FP/src/unittest/python/test_json_tests.py", line 210, in test_Case_NV
    date_signature = my_manager.cancel_appointment(cancellation_json)
AttributeError: '__VaccineManager' object has no attribute 'cancel_appointment'
]]></error>
	</testcase>
	<testcase classname="test_json_tests.TestJsons" name="test_Case_NV (test='Case_NV_46')" time="0.000" timestamp="0001-01-01T00:00:00">
		<error type="AttributeError" message="'__VaccineManager' object has no attribute 'cancel_appointment'"><![CDATA[Traceback (most recent call last):
  File "/usr/local/Cellar/python@3.8/3.8.12_1/Frameworks/Python.framework/Versions/3.8/lib/python3.8/unittest/case.py", line 60, in testPartExecutor
    yield
  File "/usr/local/Cellar/python@3.8/3.8.12_1/Frameworks/Python.framework/Versions/3.8/lib/python3.8/unittest/case.py", line 582, in subTest
    yield
  File "/Users/aaron/PycharmProjects/G89.2022.T21.FP/src/unittest/python/test_json_tests.py", line 210, in test_Case_NV
    date_signature = my_manager.cancel_appointment(cancellation_json)
AttributeError: '__VaccineManager' object has no attribute 'cancel_appointment'
]]></error>
	</testcase>
	<testcase classname="test_json_tests.TestJsons" name="test_Case_NV (test='Case_NV_47')" time="0.000" timestamp="0001-01-01T00:00:00">
		<error type="AttributeError" message="'__VaccineManager' object has no attribute 'cancel_appointment'"><![CDATA[Traceback (most recent call last):
  File "/usr/local/Cellar/python@3.8/3.8.12_1/Frameworks/Python.framework/Versions/3.8/lib/python3.8/unittest/case.py", line 60, in testPartExecutor
    yield
  File "/usr/local/Cellar/python@3.8/3.8.12_1/Frameworks/Python.framework/Versions/3.8/lib/python3.8/unittest/case.py", line 582, in subTest
    yield
  File "/Users/aaron/PycharmProjects/G89.2022.T21.FP/src/unittest/python/test_json_tests.py", line 210, in test_Case_NV
    date_signature = my_manager.cancel_appointment(cancellation_json)
AttributeError: '__VaccineManager' object has no attribute 'cancel_appointment'
]]></error>
	</testcase>
	<testcase classname="test_json_tests.TestJsons" name="test_Case_NV (test='Case_NV_48')" time="0.000" timestamp="0001-01-01T00:00:00">
		<error type="AttributeError" message="'__VaccineManager' object has no attribute 'cancel_appointment'"><![CDATA[Traceback (most recent call last):
  File "/usr/local/Cellar/python@3.8/3.8.12_1/Frameworks/Python.framework/Versions/3.8/lib/python3.8/unittest/case.py", line 60, in testPartExecutor
    yield
  File "/usr/local/Cellar/python@3.8/3.8.12_1/Frameworks/Python.framework/Versions/3.8/lib/python3.8/unittest/case.py", line 582, in subTest
    yield
  File "/Users/aaron/PycharmProjects/G89.2022.T21.FP/src/unittest/python/test_json_tests.py", line 210, in test_Case_NV
    date_signature = my_manager.cancel_appointment(cancellation_json)
AttributeError: '__VaccineManager' object has no attribute 'cancel_appointment'
]]></error>
	</testcase>
	<testcase classname="test_json_tests.TestJsons" name="test_Case_NV (test='Case_NV_49')" time="0.000" timestamp="0001-01-01T00:00:00">
		<error type="AttributeError" message="'__VaccineManager' object has no attribute 'cancel_appointment'"><![CDATA[Traceback (most recent call last):
  File "/usr/local/Cellar/python@3.8/3.8.12_1/Frameworks/Python.framework/Versions/3.8/lib/python3.8/unittest/case.py", line 60, in testPartExecutor
    yield
  File "/usr/local/Cellar/python@3.8/3.8.12_1/Frameworks/Python.framework/Versions/3.8/lib/python3.8/unittest/case.py", line 582, in subTest
    yield
  File "/Users/aaron/PycharmProjects/G89.2022.T21.FP/src/unittest/python/test_json_tests.py", line 210, in test_Case_NV
    date_signature = my_manager.cancel_appointment(cancellation_json)
AttributeError: '__VaccineManager' object has no attribute 'cancel_appointment'
]]></error>
	</testcase>
	<testcase classname="test_json_tests.TestJsons" name="test_Case_NV (test='Case_NV_50')" time="0.000" timestamp="0001-01-01T00:00:00">
		<error type="AttributeError" message="'__VaccineManager' object has no attribute 'cancel_appointment'"><![CDATA[Traceback (most recent call last):
  File "/usr/local/Cellar/python@3.8/3.8.12_1/Frameworks/Python.framework/Versions/3.8/lib/python3.8/unittest/case.py", line 60, in testPartExecutor
    yield
  File "/usr/local/Cellar/python@3.8/3.8.12_1/Frameworks/Python.framework/Versions/3.8/lib/python3.8/unittest/case.py", line 582, in subTest
    yield
  File "/Users/aaron/PycharmProjects/G89.2022.T21.FP/src/unittest/python/test_json_tests.py", line 210, in test_Case_NV
    date_signature = my_manager.cancel_appointment(cancellation_json)
AttributeError: '__VaccineManager' object has no attribute 'cancel_appointment'
]]></error>
	</testcase>
	<testcase classname="test_json_tests.TestJsons" name="test_Case_NV (test='Case_NV_51')" time="0.000" timestamp="0001-01-01T00:00:00">
		<error type="AttributeError" message="'__VaccineManager' object has no attribute 'cancel_appointment'"><![CDATA[Traceback (most recent call last):
  File "/usr/local/Cellar/python@3.8/3.8.12_1/Frameworks/Python.framework/Versions/3.8/lib/python3.8/unittest/case.py", line 60, in testPartExecutor
    yield
  File "/usr/local/Cellar/python@3.8/3.8.12_1/Frameworks/Python.framework/Versions/3.8/lib/python3.8/unittest/case.py", line 582, in subTest
    yield
  File "/Users/aaron/PycharmProjects/G89.2022.T21.FP/src/unittest/python/test_json_tests.py", line 210, in test_Case_NV
    date_signature = my_manager.cancel_appointment(cancellation_json)
AttributeError: '__VaccineManager' object has no attribute 'cancel_appointment'
]]></error>
	</testcase>
	<testcase classname="test_json_tests.TestJsons" name="test_Case_NV (test='Case_NV_52')" time="0.000" timestamp="0001-01-01T00:00:00">
		<error type="AttributeError" message="'__VaccineManager' object has no attribute 'cancel_appointment'"><![CDATA[Traceback (most recent call last):
  File "/usr/local/Cellar/python@3.8/3.8.12_1/Frameworks/Python.framework/Versions/3.8/lib/python3.8/unittest/case.py", line 60, in testPartExecutor
    yield
  File "/usr/local/Cellar/python@3.8/3.8.12_1/Frameworks/Python.framework/Versions/3.8/lib/python3.8/unittest/case.py", line 582, in subTest
    yield
  File "/Users/aaron/PycharmProjects/G89.2022.T21.FP/src/unittest/python/test_json_tests.py", line 210, in test_Case_NV
    date_signature = my_manager.cancel_appointment(cancellation_json)
AttributeError: '__VaccineManager' object has no attribute 'cancel_appointment'
]]></error>
	</testcase>
	<testcase classname="test_json_tests.TestJsons" name="test_Case_NV (test='Case_NV_53')" time="0.000" timestamp="0001-01-01T00:00:00">
		<error type="AttributeError" message="'__VaccineManager' object has no attribute 'cancel_appointment'"><![CDATA[Traceback (most recent call last):
  File "/usr/local/Cellar/python@3.8/3.8.12_1/Frameworks/Python.framework/Versions/3.8/lib/python3.8/unittest/case.py", line 60, in testPartExecutor
    yield
  File "/usr/local/Cellar/python@3.8/3.8.12_1/Frameworks/Python.framework/Versions/3.8/lib/python3.8/unittest/case.py", line 582, in subTest
    yield
  File "/Users/aaron/PycharmProjects/G89.2022.T21.FP/src/unittest/python/test_json_tests.py", line 210, in test_Case_NV
    date_signature = my_manager.cancel_appointment(cancellation_json)
AttributeError: '__VaccineManager' object has no attribute 'cancel_appointment'
]]></error>
	</testcase>
	<testcase classname="test_json_tests.TestJsons" name="test_Case_NV (test='Case_NV_54')" time="0.000" timestamp="0001-01-01T00:00:00">
		<error type="AttributeError" message="'__VaccineManager' object has no attribute 'cancel_appointment'"><![CDATA[Traceback (most recent call last):
  File "/usr/local/Cellar/python@3.8/3.8.12_1/Frameworks/Python.framework/Versions/3.8/lib/python3.8/unittest/case.py", line 60, in testPartExecutor
    yield
  File "/usr/local/Cellar/python@3.8/3.8.12_1/Frameworks/Python.framework/Versions/3.8/lib/python3.8/unittest/case.py", line 582, in subTest
    yield
  File "/Users/aaron/PycharmProjects/G89.2022.T21.FP/src/unittest/python/test_json_tests.py", line 210, in test_Case_NV
    date_signature = my_manager.cancel_appointment(cancellation_json)
AttributeError: '__VaccineManager' object has no attribute 'cancel_appointment'
]]></error>
	</testcase>
	<testcase classname="test_json_tests.TestJsons" name="test_Case_NV (test='Case_NV_55')" time="0.000" timestamp="0001-01-01T00:00:00">
		<error type="AttributeError" message="'__VaccineManager' object has no attribute 'cancel_appointment'"><![CDATA[Traceback (most recent call last):
  File "/usr/local/Cellar/python@3.8/3.8.12_1/Frameworks/Python.framework/Versions/3.8/lib/python3.8/unittest/case.py", line 60, in testPartExecutor
    yield
  File "/usr/local/Cellar/python@3.8/3.8.12_1/Frameworks/Python.framework/Versions/3.8/lib/python3.8/unittest/case.py", line 582, in subTest
    yield
  File "/Users/aaron/PycharmProjects/G89.2022.T21.FP/src/unittest/python/test_json_tests.py", line 210, in test_Case_NV
    date_signature = my_manager.cancel_appointment(cancellation_json)
AttributeError: '__VaccineManager' object has no attribute 'cancel_appointment'
]]></error>
	</testcase>
	<testcase classname="test_json_tests.TestJsons" name="test_Case_NV (test='Case_NV_56')" time="0.222" timestamp="2022-05-20T18:39:19">
		<error type="AttributeError" message="'__VaccineManager' object has no attribute 'cancel_appointment'"><![CDATA[Traceback (most recent call last):
  File "/usr/local/Cellar/python@3.8/3.8.12_1/Frameworks/Python.framework/Versions/3.8/lib/python3.8/unittest/case.py", line 60, in testPartExecutor
    yield
  File "/usr/local/Cellar/python@3.8/3.8.12_1/Frameworks/Python.framework/Versions/3.8/lib/python3.8/unittest/case.py", line 582, in subTest
    yield
  File "/Users/aaron/PycharmProjects/G89.2022.T21.FP/src/unittest/python/test_json_tests.py", line 210, in test_Case_NV
    date_signature = my_manager.cancel_appointment(cancellation_json)
AttributeError: '__VaccineManager' object has no attribute 'cancel_appointment'
]]></error>
	</testcase>
	<testcase classname="test_json_tests.TestJsons" name="test_Case_Valid" time="0.005" timestamp="2022-05-20T18:39:19">
		<error type="AttributeError" message="'__VaccineManager' object has no attribute 'cancel_appointment'"><![CDATA[Traceback (most recent call last):
  File "/usr/local/Cellar/python@3.8/3.8.12_1/Frameworks/Python.framework/Versions/3.8/lib/python3.8/unittest/case.py", line 60, in testPartExecutor
    yield
  File "/usr/local/Cellar/python@3.8/3.8.12_1/Frameworks/Python.framework/Versions/3.8/lib/python3.8/unittest/case.py", line 676, in run
    self._callTestMethod(testMethod)
  File "/usr/local/Cellar/python@3.8/3.8.12_1/Frameworks/Python.framework/Versions/3.8/lib/python3.8/unittest/case.py", line 633, in _callTestMethod
    method()
  File "/Users/aaron/PycharmProjects/G89.2022.T21.FP/venv/lib/python3.8/site-packages/freezegun/api.py", line 789, in wrapper
    result = func(*args, **kwargs)
  File "/Users/aaron/PycharmProjects/G89.2022.T21.FP/src/unittest/python/test_json_tests.py", line 187, in test_Case_Valid
    date_signature = my_manager.cancel_appointment(valid_json)
AttributeError: '__VaccineManager' object has no attribute 'cancel_appointment'
]]></error>
	</testcase>
</testsuite>
